Workbook

Sheet Tổng quan
B1: THNG – BÁO CÁO MUA HÀNG THEO DỰ ÁN
B2: Tổng quan & KPI – tự động tổng hợp từ các sheet chi tiết
B4: THAM SỐ (ô vàng – nhập tay)
B5: Tên đơn vị | C5: THNG
B6: Người lập báo cáo | C6: Phòng Mua hàng
B7: Năm báo cáo | C7: 2026 | D7: Điều khiển sheet "Báo cáo tháng"
B8: Ngưỡng tỷ lệ hàng lỗi cho phép | C8: 0.02 | D8: Tỷ lệ lỗi <= ngưỡng => "Đạt"
B9: Ngày cập nhật | C9: =TODAY() -> 46234 | D9: Tự động theo ngày mở file
B11: A. TIẾP NHẬN & XỬ LÝ YÊU CẦU CHECK GIÁ (quy trình 1)
B12: Số yêu cầu check giá đã tiếp nhận | C12: =COUNTIF('Check giá'!$A$4:$A$203,"?*") -> 2
B13: Số YC đã trả giá | C13: =COUNTIF('Check giá'!$N$4:$N$203,"Đã trả giá") -> 1
B14: Số YC đang xử lý | C14: =COUNTIF('Check giá'!$O$4:$O$203,"Đang xử lý") -> 0
B15: Số YC quá hạn chưa trả giá | C15: =COUNTIF('Check giá'!$O$4:$O$203,"Quá hạn chưa trả") -> 1
B16: Tỷ lệ trả giá đúng hạn (SLA) | C16: =IFERROR(COUNTIF('Check giá'!$O$4:$O$203,"Đúng hạn")/(COUNTIF('Check giá'!$O$4:$O$203,"Đúng hạn")+COUNTIF('Check giá'!$O$4:$O$203,"Trả trễ")),"") -> 1
B17: Thời gian xử lý bình quân (ngày) | C17: =IFERROR(AVERAGEIFS('Check giá'!$M$4:$M$203,'Check giá'!$M$4:$M$203,">=0"),"") -> 5
B18: Số NCC báo giá bình quân / yêu cầu | C18: =IFERROR(AVERAGEIFS('Check giá'!$P$4:$P$203,'Check giá'!$A$4:$A$203,"?*"),"") -> 1.5
B19: Tổng dự toán các yêu cầu check giá | C19: =SUM('Check giá'!$J$4:$J$203) -> 1366000000
B20: Tổng giá chốt sau khi hỏi giá | C20: =SUM('Check giá'!$R$4:$R$203) -> 236000000
B21: Chênh lệch giá chốt so dự toán | C21: =SUM('Check giá'!$S$4:$S$203) -> -14000000 | D21: Âm = chốt thấp hơn dự toán
B23: B. PR – PO – HỢP ĐỒNG (quy trình 2)
B24: Số đề nghị mua hàng (PR) | C24: =COUNTIF(PR!$A$4:$A$203,"?*") -> 1
B25: Số PR đã duyệt | C25: =COUNTIF(PR!$N$4:$N$203,"Đã duyệt") -> 1
B26: Tổng giá trị dự toán PR | C26: =SUM(PR!$L$4:$L$203) -> 250000000
B27: Số PO đã phát hành | C27: =COUNTIF(PO!$A$4:$A$203,"?*") -> 1
B28: Tổng giá trị PO phát hành | C28: =SUM(PO!$L$4:$L$203) -> 236000000
B29: Dự toán của các PR đã ra PO | C29: =SUM(PO!$M$4:$M$203) -> 250000000
B30: Tiết kiệm được sau đàm phán | C30: =SUM(PO!$N$4:$N$203) -> 14000000 | D30: Dự toán PR – giá trị PO thực tế
B31: Tỷ lệ tiết kiệm | C31: =IFERROR($C$30/$C$29,"") -> 0.056
B33: C. TIẾN ĐỘ GIAO HÀNG & CHẤT LƯỢNG (quy trình 2)
B34: Số PO đã đến hạn giao | C34: =COUNTIF(PO!$S$4:$S$203,"Đúng hạn")+COUNTIF(PO!$S$4:$S$203,"Giao trễ")+COUNTIF(PO!$S$4:$S$203,"Trễ hạn") -> 1
B35: Số PO giao đúng hạn | C35: =COUNTIF(PO!$S$4:$S$203,"Đúng hạn") -> 0
B36: Số PO giao trễ (đã nhận nhưng trễ) | C36: =COUNTIF(PO!$S$4:$S$203,"Giao trễ") -> 1
B37: Số PO trễ hạn (quá hạn, chưa giao) | C37: =COUNTIF(PO!$S$4:$S$203,"Trễ hạn") -> 0
B38: Tỷ lệ giao đúng hạn của NCC | C38: =IFERROR($C$35/$C$34,"") -> 0 | D38: Trên số PO đã đến hạn giao
B39: Số PO đã kiểm tra chất lượng | C39: =COUNTIF(PO!$Y$4:$Y$203,"Đạt")+COUNTIF(PO!$Y$4:$Y$203,"Không đạt") -> 1
B40: Số PO đạt chất lượng | C40: =COUNTIF(PO!$Y$4:$Y$203,"Đạt") -> 1
B41: Tỷ lệ hàng đạt chất lượng | C41: =IFERROR($C$40/$C$39,"") -> 1
B42: Tỷ lệ hàng lỗi bình quân | C42: =IFERROR(SUM(PO!$V$4:$V$203)/SUM(PO!$U$4:$U$203),"") -> 0.015
B44: D. THANH TOÁN & CÔNG NỢ PHẢI TRẢ (quy trình 3)
B45: Tổng giá trị PO | C45: =$C$28 -> 236000000
...

Sheet Hướng dẫn
B1: HƯỚNG DẪN SỬ DỤNG – BÁO CÁO MUA HÀNG THEO DỰ ÁN (THNG)
B3: I. QUY ƯỚC MÀU SẮC
B4: Chữ XANH DƯƠNG | C4: Ô nhập tay – người dùng gõ dữ liệu vào.
B5: Chữ ĐEN | C5: Ô công thức – KHÔNG gõ đè, sẽ đứt chuỗi liên kết dữ liệu.
B6: Ô nền VÀNG | C6: Tham số điều chỉnh (sheet "Tổng quan" ô C5:C8).
B7: Dòng tô ĐỎ | C7: Cảnh báo tự động: trả giá trễ, giao trễ / trễ hạn, chất lượng không đạt, nợ quá hạn, vượt ngân sách dự án.
B8: Dòng tô XANH LÁ | C8: Báo giá của NCC được chọn; PO đã thanh toán đủ.
B9: Màu thẻ sheet | C9: Xanh nhạt = quy trình 1 (check giá) · Xanh đậm = quy trình 2 (PO/HĐ/tiến độ/chất lượng) · Xanh lá = quy trình 3 (thanh toán/công nợ) · Cam = danh mục · Đỏ = báo cáo.
B11: II. QUY TRÌNH 1 – TIẾP NHẬN & XỬ LÝ YÊU CẦU CHECK GIÁ
B12: Sheet "Dự án" | C12: Khai báo danh mục dự án trước tiên: mã dự án, chủ đầu tư, PM, ngân sách mua hàng, trạng thái.
B13: Sheet "Check giá" | C13: Phòng Dự án/Đấu thầu gửi yêu cầu check giá → nhập Mã YC, Ngày nhận, Mã dự án (tự kéo tên dự án), hạng mục, số lượng, đơn giá dự toán, HẠN TRẢ GIÁ. Khi trả giá xong nhập Ngày trả giá thực tế → tự tính số ngày xử lý và đánh giá SLA: Đúng hạn / Trả trễ / Quá hạn chưa trả / Đang xử lý.
B14: Sheet "Báo giá" | C14: Mỗi dòng = 1 báo giá của 1 NCC cho 1 Mã YC. Nhập Mã YC + Mã NCC → tự kéo dự án, hạng mục, số lượng, dự toán, tên NCC, điều khoản TT. Nhập đơn giá → tự tính thành tiền, giá thấp nhất của YC, chênh lệch so giá thấp nhất và so dự toán. Đánh "x" ở cột NCC được chọn.
B15: Kết quả trả về | C15: Sheet "Check giá" tự lấy đơn giá chốt / giá trị chốt từ dòng báo giá được chọn, tự đếm số NCC đã báo giá và tự báo đã lập PR hay chưa.
B17: III. QUY TRÌNH 2 – PO, HỢP ĐỒNG, TIẾN ĐỘ & CHẤT LƯỢNG
B18: Sheet "PR" | C18: Khi dự án trúng thầu/duyệt mua: nhập Mã PR + Mã YC → tự kéo dự án, bộ phận, hạng mục, ĐVT và đơn giá chốt từ bước check giá. Nhập số lượng và đơn giá dự toán → ra giá trị dự toán. Cập nhật trạng thái duyệt.
B19: Sheet "PO" | C19: Nhập Mã PO + Mã PR + Mã NCC → tự kéo dự án, hạng mục, bộ phận, dự toán PR, tên NCC, điều khoản TT. Nhập số lượng/đơn giá → giá trị PO và tiết kiệm đàm phán. Nhập số hợp đồng, ngày ký HĐ.
B20: Theo dõi tiến độ | C20: Nhập Ngày giao cam kết và Ngày nhận thực tế → tự đánh giá: chưa nhận & chưa tới hạn = "Chưa đến hạn"; chưa nhận & đã quá hạn = "Trễ hạn"; nhận <= cam kết = "Đúng hạn"; nhận > cam kết = "Giao trễ". Số ngày trễ tự tính.
B21: Theo dõi chất lượng | C21: Nhập SL nhận thực tế và SL hàng lỗi → tỷ lệ hàng lỗi tự tính; so với ngưỡng ở ô vàng "Tổng quan"!C8 để chấm "Đạt" / "Không đạt". Nhập thêm SL trả lại NCC.
B23: IV. QUY TRÌNH 3 – THEO DÕI TÌNH TRẠNG THANH TOÁN
B24: Hạn thanh toán | C24: Tự tính tại sheet "PO" = Ngày nhận thực tế + Điều khoản thanh toán (số ngày) của NCC.
B25: Sheet "Thanh toán" | C25: Sổ chi tiền. Một PO chi nhiều đợt = nhiều dòng. Nhập Mã PO → tự kéo dự án, NCC, giá trị PO; luỹ kế đã trả và số còn phải trả của PO tự tính.
B26: Sheet "Công nợ" | C26: 100% công thức, không nhập tay. Tự tổng hợp theo từng dòng PO: đã trả, còn phải trả, số ngày quá hạn, nhóm tuổi nợ (Trong hạn / 1-30 / 31-60 / 61-90 / >90), trạng thái.
B28: V. BÁO CÁO
B29: Tổng quan | C29: KPI toàn bộ, chia đúng 3 nhóm quy trình + phần dự án.
B30: Báo cáo tháng | C30: 12 tháng của năm tại ô vàng "Tổng quan"!C7: yêu cầu check giá, SLA trả giá, giá trị PR, giá trị PO, tiết kiệm, giao đúng hạn, chất lượng, tiền đã chi.
B31: Thống kê NCC | C31: Giá trị mua, tỷ lệ trúng thầu, giao đúng hạn, tỷ lệ hàng lỗi, công nợ và nợ quá hạn theo từng NCC.
B32: Thống kê dự án | C32: Ngân sách, giá trị YC/PR/PO, tiết kiệm, % sử dụng ngân sách, giao hàng, đã trả – còn nợ – nợ quá hạn theo từng dự án.
B34: VI. QUY ƯỚC MÃ & ĐỊNH DẠNG
B35: Mã dự án | C35: DA-YYYY-nn.
B36: Mã yêu cầu check giá | C36: YC-YYYY-nnn.
B37: Mã báo giá / PR / PO / phiếu chi | C37: BG-YYYY-nnn · PR-YYYY-nnn · PO-YYYY-nnn · PC-YYYY-nnn.
B38: Nguyên tắc nối chuỗi | C38: Mã ở bước sau phải trùng khớp tuyệt đối mã bước trước (không thừa dấu cách) thì công thức mới kéo được dữ liệu.
B39: Định dạng | C39: Font Arial · tiền #,##0 · tỷ lệ dạng % (lưu dạng phân số) · ngày dd/mm/yyyy.
B41: VII. LƯU Ý
B42: Số dòng | C42: Công thức kéo sẵn 200 dòng (dòng 4 → 203) mỗi sheet. Cần thêm thì copy dòng cuối kéo xuống.
B43: Dữ liệu ví dụ | C43: Chuỗi mẫu: DA-2026-01 → YC-2026-001 → BG-2026-001/002/003 → PR-2026-001 → PO-2026-001 → PC-2026-001/002. YC-2026-002 là ví dụ yêu cầu quá hạn chưa trả giá. XOÁ TRƯỚC KHI DÙNG THẬT.
B45: Ví dụ ô nhập tay | C45: Ví dụ ô công thức

Sheet Dự án
A1: DANH MỤC DỰ ÁN
A2: Khai báo trước tiên. Mã dự án là khoá liên kết cho toàn bộ chuỗi mua hàng.
A3: Mã dự án | B3: Tên dự án | C3: Khách hàng / Chủ đầu tư | D3: Quản lý dự án (PM) | E3: Ngày bắt đầu | F3: Ngày kết thúc dự kiến | G3: Ngân sách mua hàng | H3: Trạng thái dự án | I3: Ghi chú
A4: DA-2026-01 | B4: Nhà máy Bao bì Tân Uyên – Giai đoạn 2 | C4: Công ty CP Bao bì Tân Uyên | D4: Phạm Minh Đức | E4: 46024 | F4: 46295 | G4: 5000000000 | H4: Đang thực hiện | I4: VÍ DỤ MẪU – XOÁ TRƯỚC KHI DÙNG THẬT
A5: DA-2026-02 | B5: Kho lạnh Long An | C5: Công ty TNHH Thực phẩm Long An | D5: Vũ Thị Hà | E5: 46027 | F5: 46387 | G5: 3200000000 | H5: Đang chào giá | I5: VÍ DỤ MẪU – XOÁ TRƯỚC KHI DÙNG THẬT

Sheet Nhà cung cấp
A1: DANH MỤC NHÀ CUNG CẤP
A2: Toàn bộ nhập tay. Mã NCC duy nhất – khoá liên kết cho báo giá, PO, thanh toán.
A3: Mã NCC | B3: Tên nhà cung cấp | C3: Người liên hệ | D3: Điện thoại | E3: Email | F3: Địa chỉ | G3: Điều khoản TT (ngày) | H3: Đánh giá NCC | I3: Nhóm hàng cung cấp | J3: Mã số thuế | K3: Ghi chú
A4: NCC001 | B4: Công ty TNHH Thép Việt An | C4: Nguyễn Văn Bình | D4: 0901234567 | E4: binh.nv@vietan.com.vn | F4: 12 Lê Lợi, Q.1, TP.HCM | G4: 30 | H4: A | I4: Thép tấm, thép hình | J4: 0301234567 | K4: VÍ DỤ MẪU – XOÁ TRƯỚC KHI DÙNG THẬT
A5: NCC002 | B5: Công ty CP Vật tư Hoàng Long | C5: Trần Thị Mai | D5: 0912345678 | E5: mai.tt@hoanglong.vn | F5: 45 Nguyễn Trãi, Thanh Xuân, Hà Nội | G5: 45 | H5: B | I5: Thép tấm, vật tư phụ | J5: 0102345678 | K5: VÍ DỤ MẪU – XOÁ TRƯỚC KHI DÙNG THẬT
A6: NCC003 | B6: Công ty TNHH TM Đại Phát | C6: Lê Quốc Huy | D6: 0923456789 | E6: huy.lq@daiphat.vn | F6: 88 Trần Phú, Hải Châu, Đà Nẵng | G6: 15 | H6: B | I6: Thép tấm, inox | J6: 0401234567 | K6: VÍ DỤ MẪU – XOÁ TRƯỚC KHI DÙNG THẬT

Sheet Check giá
A1: QUY TRÌNH 1 – TIẾP NHẬN & XỬ LÝ YÊU CẦU CHECK GIÁ
A2: Nhập Mã dự án → tự kéo tên dự án. Nhập Hạn trả giá và Ngày trả giá thực tế → tự tính số ngày xử lý và đánh giá SLA. Đơn giá/giá trị chốt tự lấy từ báo giá được chọn.
A3: Mã YC | B3: Ngày nhận yêu cầu | C3: Mã dự án | D3: Tên dự án | E3: Người / Bộ phận yêu cầu | F3: Hạng mục cần check giá | G3: ĐVT | H3: Số lượng | I3: Đơn giá dự toán | J3: Giá trị dự toán | K3: Hạn trả giá | L3: Ngày trả giá thực tế | M3: Số ngày xử lý | N3: Trạng thái xử lý | O3: Đánh giá SLA | P3: Số NCC đã báo giá | Q3: Đơn giá chốt | R3: Giá trị chốt | S3: Chênh lệch so dự toán | T3: Tình trạng lập PR | U3: Ghi chú
A4: YC-2026-001 | B4: 46025 | C4: DA-2026-01 | D4: =IF($C4="","",IFERROR(INDEX('Dự án'!$B$4:$B$203,MATCH($C4,'Dự án'!$A$4:$A$203,0)),"")) -> Nhà máy Bao bì Tân Uyên – Giai đoạn 2 | E4: Phòng Dự án – Trần Văn Nam | F4: Thép tấm SS400 dày 10mm (1500x6000) | G4: Tấm | H4: 200 | I4: 1250000 | J4: =IF($A4="","",$H4*$I4) -> 250000000 | K4: 46031 | L4: 46030 | M4: =IF($A4="","",IF($L4="","",$L4-$B4)) -> 5 | N4: Đã trả giá | O4: =IF($A4="","",IF($K4="","",IF($L4="",IF(TODAY()>$K4,"Quá hạn chưa trả","Đang xử lý"),IF($L4<=$K4,"Đúng hạn","Trả trễ")))) -> Đúng hạn | P4: =IF($A4="","",COUNTIFS('Báo giá'!$C$4:$C$203,$A4)) -> 3 | Q4: =IF($A4="","",IF(SUMIFS('Báo giá'!$K$4:$K$203,'Báo giá'!$C$4:$C$203,$A4,'Báo giá'!$T$4:$T$203,"x")=0,"",SUMIFS('Báo giá'!$K$4:$K$203,'Báo giá'!$C$4:$C$203,$A4,'Báo giá'!$T$4:$T$203,"x"))) -> 1180000 | R4: =IF($A4="","",IF(SUMIFS('Báo giá'!$L$4:$L$203,'Báo giá'!$C$4:$C$203,$A4,'Báo giá'!$T$4:$T$203,"x")=0,"",SUMIFS('Báo giá'!$L$4:$L$203,'Báo giá'!$C$4:$C$203,$A4,'Báo giá'!$T$4:$T$203,"x"))) -> 236000000 | S4: =IF($A4="","",IF($R4="","",$R4-$J4)) -> -14000000 | T4: =IF($A4="","",IF(COUNTIFS(PR!$C$4:$C$203,$A4)>0,"Đã lập PR","Chưa lập PR")) -> Đã lập PR | U4: VÍ DỤ MẪU – XOÁ TRƯỚC KHI DÙNG THẬT
A5: YC-2026-002 | B5: 46028 | C5: DA-2026-02 | D5: =IF($C5="","",IFERROR(INDEX('Dự án'!$B$4:$B$203,MATCH($C5,'Dự án'!$A$4:$A$203,0)),"")) -> Kho lạnh Long An | E5: Phòng Đấu thầu – Lê Thu Hằng | F5: Panel cách nhiệt PU 100mm | G5: m2 | H5: 1800 | I5: 620000 | J5: =IF($A5="","",$H5*$I5) -> 1116000000 | K5: 46034 | M5: =IF($A5="","",IF($L5="","",$L5-$B5)) | N5: Đang hỏi giá | O5: =IF($A5="","",IF($K5="","",IF($L5="",IF(TODAY()>$K5,"Quá hạn chưa trả","Đang xử lý"),IF($L5<=$K5,"Đúng hạn","Trả trễ")))) -> Quá hạn chưa trả | P5: =IF($A5="","",COUNTIFS('Báo giá'!$C$4:$C$203,$A5)) -> 0 | Q5: =IF($A5="","",IF(SUMIFS('Báo giá'!$K$4:$K$203,'Báo giá'!$C$4:$C$203,$A5,'Báo giá'!$T$4:$T$203,"x")=0,"",SUMIFS('Báo giá'!$K$4:$K$203,'Báo giá'!$C$4:$C$203,$A5,'Báo giá'!$T$4:$T$203,"x"))) | R5: =IF($A5="","",IF(SUMIFS('Báo giá'!$L$4:$L$203,'Báo giá'!$C$4:$C$203,$A5,'Báo giá'!$T$4:$T$203,"x")=0,"",SUMIFS('Báo giá'!$L$4:$L$203,'Báo giá'!$C$4:$C$203,$A5,'Báo giá'!$T$4:$T$203,"x"))) | S5: =IF($A5="","",IF($R5="","",$R5-$J5)) | T5: =IF($A5="","",IF(COUNTIFS(PR!$C$4:$C$203,$A5)>0,"Đã lập PR","Chưa lập PR")) -> Chưa lập PR | U5: VÍ DỤ MẪU – XOÁ TRƯỚC KHI DÙNG THẬT
D6: =IF($C6="","",IFERROR(INDEX('Dự án'!$B$4:$B$203,MATCH($C6,'Dự án'!$A$4:$A$203,0)),"")) | J6: =IF($A6="","",$H6*$I6) | M6: =IF($A6="","",IF($L6="","",$L6-$B6)) | O6: =IF($A6="","",IF($K6="","",IF($L6="",IF(TODAY()>$K6,"Quá hạn chưa trả","Đang xử lý"),IF($L6<=$K6,"Đúng hạn","Trả trễ")))) | P6: =IF($A6="","",COUNTIFS('Báo giá'!$C$4:$C$203,$A6)) | Q6: =IF($A6="","",IF(SUMIFS('Báo giá'!$K$4:$K$203,'Báo giá'!$C$4:$C$203,$A6,'Báo giá'!$T$4:$T$203,"x")=0,"",SUMIFS('Báo giá'!$K$4:$K$203,'Báo giá'!$C$4:$C$203,$A6,'Báo giá'!$T$4:$T$203,"x"))) | R6: =IF($A6="","",IF(SUMIFS('Báo giá'!$L$4:$L$203,'Báo giá'!$C$4:$C$203,$A6,'Báo giá'!$T$4:$T$203,"x")=0,"",SUMIFS('Báo giá'!$L$4:$L$203,'Báo giá'!$C$4:$C$203,$A6,'Báo giá'!$T$4:$T$203,"x"))) | S6: =IF($A6="","",IF($R6="","",$R6-$J6)) | T6: =IF($A6="","",IF(COUNTIFS(PR!$C$4:$C$203,$A6)>0,"Đã lập PR","Chưa lập PR"))
D7: =IF($C7="","",IFERROR(INDEX('Dự án'!$B$4:$B$203,MATCH($C7,'Dự án'!$A$4:$A$203,0)),"")) | J7: =IF($A7="","",$H7*$I7) | M7: =IF($A7="","",IF($L7="","",$L7-$B7)) | O7: =IF($A7="","",IF($K7="","",IF($L7="",IF(TODAY()>$K7,"Quá hạn chưa trả","Đang xử lý"),IF($L7<=$K7,"Đúng hạn","Trả trễ")))) | P7: =IF($A7="","",COUNTIFS('Báo giá'!$C$4:$C$203,$A7)) | Q7: =IF($A7="","",IF(SUMIFS('Báo giá'!$K$4:$K$203,'Báo giá'!$C$4:$C$203,$A7,'Báo giá'!$T$4:$T$203,"x")=0,"",SUMIFS('Báo giá'!$K$4:$K$203,'Báo giá'!$C$4:$C$203,$A7,'Báo giá'!$T$4:$T$203,"x"))) | R7: =IF($A7="","",IF(SUMIFS('Báo giá'!$L$4:$L$203,'Báo giá'!$C$4:$C$203,$A7,'Báo giá'!$T$4:$T$203,"x")=0,"",SUMIFS('Báo giá'!$L$4:$L$203,'Báo giá'!$C$4:$C$203,$A7,'Báo giá'!$T$4:$T$203,"x"))) | S7: =IF($A7="","",IF($R7="","",$R7-$J7)) | T7: =IF($A7="","",IF(COUNTIFS(PR!$C$4:$C$203,$A7)>0,"Đã lập PR","Chưa lập PR"))
D8: =IF($C8="","",IFERROR(INDEX('Dự án'!$B$4:$B$203,MATCH($C8,'Dự án'!$A$4:$A$203,0)),"")) | J8: =IF($A8="","",$H8*$I8) | M8: =IF($A8="","",IF($L8="","",$L8-$B8)) | O8: =IF($A8="","",IF($K8="","",IF($L8="",IF(TODAY()>$K8,"Quá hạn chưa trả","Đang xử lý"),IF($L8<=$K8,"Đúng hạn","Trả trễ")))) | P8: =IF($A8="","",COUNTIFS('Báo giá'!$C$4:$C$203,$A8)) | Q8: =IF($A8="","",IF(SUMIFS('Báo giá'!$K$4:$K$203,'Báo giá'!$C$4:$C$203,$A8,'Báo giá'!$T$4:$T$203,"x")=0,"",SUMIFS('Báo giá'!$K$4:$K$203,'Báo giá'!$C$4:$C$203,$A8,'Báo giá'!$T$4:$T$203,"x"))) | R8: =IF($A8="","",IF(SUMIFS('Báo giá'!$L$4:$L$203,'Báo giá'!$C$4:$C$203,$A8,'Báo giá'!$T$4:$T$203,"x")=0,"",SUMIFS('Báo giá'!$L$4:$L$203,'Báo giá'!$C$4:$C$203,$A8,'Báo giá'!$T$4:$T$203,"x"))) | S8: =IF($A8="","",IF($R8="","",$R8-$J8)) | T8: =IF($A8="","",IF(COUNTIFS(PR!$C$4:$C$203,$A8)>0,"Đã lập PR","Chưa lập PR"))
D9: =IF($C9="","",IFERROR(INDEX('Dự án'!$B$4:$B$203,MATCH($C9,'Dự án'!$A$4:$A$203,0)),"")) | J9: =IF($A9="","",$H9*$I9) | M9: =IF($A9="","",IF($L9="","",$L9-$B9)) | O9: =IF($A9="","",IF($K9="","",IF($L9="",IF(TODAY()>$K9,"Quá hạn chưa trả","Đang xử lý"),IF($L9<=$K9,"Đúng hạn","Trả trễ")))) | P9: =IF($A9="","",COUNTIFS('Báo giá'!$C$4:$C$203,$A9)) | Q9: =IF($A9="","",IF(SUMIFS('Báo giá'!$K$4:$K$203,'Báo giá'!$C$4:$C$203,$A9,'Báo giá'!$T$4:$T$203,"x")=0,"",SUMIFS('Báo giá'!$K$4:$K$203,'Báo giá'!$C$4:$C$203,$A9,'Báo giá'!$T$4:$T$203,"x"))) | R9: =IF($A9="","",IF(SUMIFS('Báo giá'!$L$4:$L$203,'Báo giá'!$C$4:$C$203,$A9,'Báo giá'!$T$4:$T$203,"x")=0,"",SUMIFS('Báo giá'!$L$4:$L$203,'Báo giá'!$C$4:$C$203,$A9,'Báo giá'!$T$4:$T$203,"x"))) | S9: =IF($A9="","",IF($R9="","",$R9-$J9)) | T9: =IF($A9="","",IF(COUNTIFS(PR!$C$4:$C$203,$A9)>0,"Đã lập PR","Chưa lập PR"))
D10: =IF($C10="","",IFERROR(INDEX('Dự án'!$B$4:$B$203,MATCH($C10,'Dự án'!$A$4:$A$203,0)),"")) | J10: =IF($A10="","",$H10*$I10) | M10: =IF($A10="","",IF($L10="","",$L10-$B10)) | O10: =IF($A10="","",IF($K10="","",IF($L10="",IF(TODAY()>$K10,"Quá hạn chưa trả","Đang xử lý"),IF($L10<=$K10,"Đúng hạn","Trả trễ")))) | P10: =IF($A10="","",COUNTIFS('Báo giá'!$C$4:$C$203,$A10)) | Q10: =IF($A10="","",IF(SUMIFS('Báo giá'!$K$4:$K$203,'Báo giá'!$C$4:$C$203,$A10,'Báo giá'!$T$4:$T$203,"x")=0,"",SUMIFS('Báo giá'!$K$4:$K$203,'Báo giá'!$C$4:$C$203,$A10,'Báo giá'!$T$4:$T$203,"x"))) | R10: =IF($A10="","",IF(SUMIFS('Báo giá'!$L$4:$L$203,'Báo giá'!$C$4:$C$203,$A10,'Báo giá'!$T$4:$T$203,"x")=0,"",SUMIFS('Báo giá'!$L$4:$L$203,'Báo giá'!$C$4:$C$203,$A10,'Báo giá'!$T$4:$T$203,"x"))) | S10: =IF($A10="","",IF($R10="","",$R10-$J10)) | T10: =IF($A10="","",IF(COUNTIFS(PR!$C$4:$C$203,$A10)>0,"Đã lập PR","Chưa lập PR"))
D11: =IF($C11="","",IFERROR(INDEX('Dự án'!$B$4:$B$203,MATCH($C11,'Dự án'!$A$4:$A$203,0)),"")) | J11: =IF($A11="","",$H11*$I11) | M11: =IF($A11="","",IF($L11="","",$L11-$B11)) | O11: =IF($A11="","",IF($K11="","",IF($L11="",IF(TODAY()>$K11,"Quá hạn chưa trả","Đang xử lý"),IF($L11<=$K11,"Đúng hạn","Trả trễ")))) | P11: =IF($A11="","",COUNTIFS('Báo giá'!$C$4:$C$203,$A11)) | Q11: =IF($A11="","",IF(SUMIFS('Báo giá'!$K$4:$K$203,'Báo giá'!$C$4:$C$203,$A11,'Báo giá'!$T$4:$T$203,"x")=0,"",SUMIFS('Báo giá'!$K$4:$K$203,'Báo giá'!$C$4:$C$203,$A11,'Báo giá'!$T$4:$T$203,"x"))) | R11: =IF($A11="","",IF(SUMIFS('Báo giá'!$L$4:$L$203,'Báo giá'!$C$4:$C$203,$A11,'Báo giá'!$T$4:$T$203,"x")=0,"",SUMIFS('Báo giá'!$L$4:$L$203,'Báo giá'!$C$4:$C$203,$A11,'Báo giá'!$T$4:$T$203,"x"))) | S11: =IF($A11="","",IF($R11="","",$R11-$J11)) | T11: =IF($A11="","",IF(COUNTIFS(PR!$C$4:$C$203,$A11)>0,"Đã lập PR","Chưa lập PR"))
D12: =IF($C12="","",IFERROR(INDEX('Dự án'!$B$4:$B$203,MATCH($C12,'Dự án'!$A$4:$A$203,0)),"")) | J12: =IF($A12="","",$H12*$I12) | M12: =IF($A12="","",IF($L12="","",$L12-$B12)) | O12: =IF($A12="","",IF($K12="","",IF($L12="",IF(TODAY()>$K12,"Quá hạn chưa trả","Đang xử lý"),IF($L12<=$K12,"Đúng hạn","Trả trễ")))) | P12: =IF($A12="","",COUNTIFS('Báo giá'!$C$4:$C$203,$A12)) | Q12: =IF($A12="","",IF(SUMIFS('Báo giá'!$K$4:$K$203,'Báo giá'!$C$4:$C$203,$A12,'Báo giá'!$T$4:$T$203,"x")=0,"",SUMIFS('Báo giá'!$K$4:$K$203,'Báo giá'!$C$4:$C$203,$A12,'Báo giá'!$T$4:$T$203,"x"))) | R12: =IF($A12="","",IF(SUMIFS('Báo giá'!$L$4:$L$203,'Báo giá'!$C$4:$C$203,$A12,'Báo giá'!$T$4:$T$203,"x")=0,"",SUMIFS('Báo giá'!$L$4:$L$203,'Báo giá'!$C$4:$C$203,$A12,'Báo giá'!$T$4:$T$203,"x"))) | S12: =IF($A12="","",IF($R12="","",$R12-$J12)) | T12: =IF($A12="","",IF(COUNTIFS(PR!$C$4:$C$203,$A12)>0,"Đã lập PR","Chưa lập PR"))
D13: =IF($C13="","",IFERROR(INDEX('Dự án'!$B$4:$B$203,MATCH($C13,'Dự án'!$A$4:$A$203,0)),"")) | J13: =IF($A13="","",$H13*$I13) | M13: =IF($A13="","",IF($L13="","",$L13-$B13)) | O13: =IF($A13="","",IF($K13="","",IF($L13="",IF(TODAY()>$K13,"Quá hạn chưa trả","Đang xử lý"),IF($L13<=$K13,"Đúng hạn","Trả trễ")))) | P13: =IF($A13="","",COUNTIFS('Báo giá'!$C$4:$C$203,$A13)) | Q13: =IF($A13="","",IF(SUMIFS('Báo giá'!$K$4:$K$203,'Báo giá'!$C$4:$C$203,$A13,'Báo giá'!$T$4:$T$203,"x")=0,"",SUMIFS('Báo giá'!$K$4:$K$203,'Báo giá'!$C$4:$C$203,$A13,'Báo giá'!$T$4:$T$203,"x"))) | R13: =IF($A13="","",IF(SUMIFS('Báo giá'!$L$4:$L$203,'Báo giá'!$C$4:$C$203,$A13,'Báo giá'!$T$4:$T$203,"x")=0,"",SUMIFS('Báo giá'!$L$4:$L$203,'Báo giá'!$C$4:$C$203,$A13,'Báo giá'!$T$4:$T$203,"x"))) | S13: =IF($A13="","",IF($R13="","",$R13-$J13)) | T13: =IF($A13="","",IF(COUNTIFS(PR!$C$4:$C$203,$A13)>0,"Đã lập PR","Chưa lập PR"))
D14: =IF($C14="","",IFERROR(INDEX('Dự án'!$B$4:$B$203,MATCH($C14,'Dự án'!$A$4:$A$203,0)),"")) | J14: =IF($A14="","",$H14*$I14) | M14: =IF($A14="","",IF($L14="","",$L14-$B14)) | O14: =IF($A14="","",IF($K14="","",IF($L14="",IF(TODAY()>$K14,"Quá hạn chưa trả","Đang xử lý"),IF($L14<=$K14,"Đúng hạn","Trả trễ")))) | P14: =IF($A14="","",COUNTIFS('Báo giá'!$C$4:$C$203,$A14)) | Q14: =IF($A14="","",IF(SUMIFS('Báo giá'!$K$4:$K$203,'Báo giá'!$C$4:$C$203,$A14,'Báo giá'!$T$4:$T$203,"x")=0,"",SUMIFS('Báo giá'!$K$4:$K$203,'Báo giá'!$C$4:$C$203,$A14,'Báo giá'!$T$4:$T$203,"x"))) | R14: =IF($A14="","",IF(SUMIFS('Báo giá'!$L$4:$L$203,'Báo giá'!$C$4:$C$203,$A14,'Báo giá'!$T$4:$T$203,"x")=0,"",SUMIFS('Báo giá'!$L$4:$L$203,'Báo giá'!$C$4:$C$203,$A14,'Báo giá'!$T$4:$T$203,"x"))) | S14: =IF($A14="","",IF($R14="","",$R14-$J14)) | T14: =IF($A14="","",IF(COUNTIFS(PR!$C$4:$C$203,$A14)>0,"Đã lập PR","Chưa lập PR"))
D15: =IF($C15="","",IFERROR(INDEX('Dự án'!$B$4:$B$203,MATCH($C15,'Dự án'!$A$4:$A$203,0)),"")) | J15: =IF($A15="","",$H15*$I15) | M15: =IF($A15="","",IF($L15="","",$L15-$B15)) | O15: =IF($A15="","",IF($K15="","",IF($L15="",IF(TODAY()>$K15,"Quá hạn chưa trả","Đang xử lý"),IF($L15<=$K15,"Đúng hạn","Trả trễ")))) | P15: =IF($A15="","",COUNTIFS('Báo giá'!$C$4:$C$203,$A15)) | Q15: =IF($A15="","",IF(SUMIFS('Báo giá'!$K$4:$K$203,'Báo giá'!$C$4:$C$203,$A15,'Báo giá'!$T$4:$T$203,"x")=0,"",SUMIFS('Báo giá'!$K$4:$K$203,'Báo giá'!$C$4:$C$203,$A15,'Báo giá'!$T$4:$T$203,"x"))) | R15: =IF($A15="","",IF(SUMIFS('Báo giá'!$L$4:$L$203,'Báo giá'!$C$4:$C$203,$A15,'Báo giá'!$T$4:$T$203,"x")=0,"",SUMIFS('Báo giá'!$L$4:$L$203,'Báo giá'!$C$4:$C$203,$A15,'Báo giá'!$T$4:$T$203,"x"))) | S15: =IF($A15="","",IF($R15="","",$R15-$J15)) | T15: =IF($A15="","",IF(COUNTIFS(PR!$C$4:$C$203,$A15)>0,"Đã lập PR","Chưa lập PR"))
D16: =IF($C16="","",IFERROR(INDEX('Dự án'!$B$4:$B$203,MATCH($C16,'Dự án'!$A$4:$A$203,0)),"")) | J16: =IF($A16="","",$H16*$I16) | M16: =IF($A16="","",IF($L16="","",$L16-$B16)) | O16: =IF($A16="","",IF($K16="","",IF($L16="",IF(TODAY()>$K16,"Quá hạn chưa trả","Đang xử lý"),IF($L16<=$K16,"Đúng hạn","Trả trễ")))) | P16: =IF($A16="","",COUNTIFS('Báo giá'!$C$4:$C$203,$A16)) | Q16: =IF($A16="","",IF(SUMIFS('Báo giá'!$K$4:$K$203,'Báo giá'!$C$4:$C$203,$A16,'Báo giá'!$T$4:$T$203,"x")=0,"",SUMIFS('Báo giá'!$K$4:$K$203,'Báo giá'!$C$4:$C$203,$A16,'Báo giá'!$T$4:$T$203,"x"))) | R16: =IF($A16="","",IF(SUMIFS('Báo giá'!$L$4:$L$203,'Báo giá'!$C$4:$C$203,$A16,'Báo giá'!$T$4:$T$203,"x")=0,"",SUMIFS('Báo giá'!$L$4:$L$203,'Báo giá'!$C$4:$C$203,$A16,'Báo giá'!$T$4:$T$203,"x"))) | S16: =IF($A16="","",IF($R16="","",$R16-$J16)) | T16: =IF($A16="","",IF(COUNTIFS(PR!$C$4:$C$203,$A16)>0,"Đã lập PR","Chưa lập PR"))
D17: =IF($C17="","",IFERROR(INDEX('Dự án'!$B$4:$B$203,MATCH($C17,'Dự án'!$A$4:$A$203,0)),"")) | J17: =IF($A17="","",$H17*$I17) | M17: =IF($A17="","",IF($L17="","",$L17-$B17)) | O17: =IF($A17="","",IF($K17="","",IF($L17="",IF(TODAY()>$K17,"Quá hạn chưa trả","Đang xử lý"),IF($L17<=$K17,"Đúng hạn","Trả trễ")))) | P17: =IF($A17="","",COUNTIFS('Báo giá'!$C$4:$C$203,$A17)) | Q17: =IF($A17="","",IF(SUMIFS('Báo giá'!$K$4:$K$203,'Báo giá'!$C$4:$C$203,$A17,'Báo giá'!$T$4:$T$203,"x")=0,"",SUMIFS('Báo giá'!$K$4:$K$203,'Báo giá'!$C$4:$C$203,$A17,'Báo giá'!$T$4:$T$203,"x"))) | R17: =IF($A17="","",IF(SUMIFS('Báo giá'!$L$4:$L$203,'Báo giá'!$C$4:$C$203,$A17,'Báo giá'!$T$4:$T$203,"x")=0,"",SUMIFS('Báo giá'!$L$4:$L$203,'Báo giá'!$C$4:$C$203,$A17,'Báo giá'!$T$4:$T$203,"x"))) | S17: =IF($A17="","",IF($R17="","",$R17-$J17)) | T17: =IF($A17="","",IF(COUNTIFS(PR!$C$4:$C$203,$A17)>0,"Đã lập PR","Chưa lập PR"))
... D203: =IF($C203="","",IFERROR(INDEX('Dự án'!$B$4:$B$203,MATCH($C203,'Dự án'!$A$4:$A$203,0)),"")) | J203: =IF($A203="","",$H203*$I203) | M203: =IF($A203="","",IF($L203="","",$L203-$B203)) | O203: =IF($A203="","",IF($K203="","",IF($L203="",IF(TODAY()>$K203,"Quá hạn chưa trả","Đang xử lý"),IF($L203<=$K203,"Đúng hạn","Trả trễ")))) | P203: =IF($A203="","",COUNTIFS('Báo giá'!$C$4:$C$203,$A203)) | Q203: =IF($A203="","",IF(SUMIFS('Báo giá'!$K$4:$K$203,'Báo giá'!$C$4:$C$203,$A203,'Báo giá'!$T$4:$T$203,"x")=0,"",SUMIFS('Báo giá'!$K$4:$K$203,'Báo giá'!$C$4:$C$203,$A203,'Báo giá'!$T$4:$T$203,"x"))) | R203: =IF($A203="","",IF(SUMIFS('Báo giá'!$L$4:$L$203,'Báo giá'!$C$4:$C$203,$A203,'Báo giá'!$T$4:$T$203,"x")=0,"",SUMIFS('Báo giá'!$L$4:$L$203,'Báo giá'!$C$4:$C$203,$A203,'Báo giá'!$T$4:$T$203,"x"))) | S203: =IF($A203="","",IF($R203="","",$R203-$J203)) | T203: =IF($A203="","",IF(COUNTIFS(PR!$C$4:$C$203,$A203)>0,"Đã lập PR","Chưa lập PR"))

Sheet Báo giá
A1: QUY TRÌNH 1 – SO SÁNH BÁO GIÁ NHÀ CUNG CẤP
A2: Mỗi dòng = 1 báo giá của 1 NCC cho 1 Mã YC. Nhập Mã YC + Mã NCC → tự kéo dự án, hạng mục, số lượng, dự toán, tên NCC, điều khoản TT.
A3: Mã báo giá | B3: Ngày báo giá | C3: Mã YC | D3: Mã dự án | E3: Tên dự án | F3: Hạng mục (từ YC) | G3: Số lượng (từ YC) | H3: Giá trị dự toán (từ YC) | I3: Mã NCC | J3: Tên NCC | K3: Đơn giá báo giá | L3: Thành tiền | M3: Thời gian giao (ngày) | N3: Điều khoản TT (ngày) | O3: Hiệu lực báo giá | P3: Giá thấp nhất của YC | Q3: Chênh lệch so giá thấp nhất | R3: Chênh lệch so dự toán | S3: % chênh so dự toán | T3: NCC được chọn (x) | U3: Mã PR phát sinh | V3: Ghi chú
A4: BG-2026-001 | B4: 46030 | C4: YC-2026-001 | D4: =IF($C4="","",IFERROR(INDEX('Check giá'!$C$4:$C$203,MATCH($C4,'Check giá'!$A$4:$A$203,0)),"")) -> DA-2026-01 | E4: =IF($C4="","",IFERROR(INDEX('Check giá'!$D$4:$D$203,MATCH($C4,'Check giá'!$A$4:$A$203,0)),"")) -> Nhà máy Bao bì Tân Uyên – Giai đoạn 2 | F4: =IF($C4="","",IFERROR(INDEX('Check giá'!$F$4:$F$203,MATCH($C4,'Check giá'!$A$4:$A$203,0)),"")) -> Thép tấm SS400 dày 10mm (1500x6000) | G4: =IF($C4="","",IFERROR(INDEX('Check giá'!$H$4:$H$203,MATCH($C4,'Check giá'!$A$4:$A$203,0)),"")) -> 200 | H4: =IF($C4="","",IFERROR(INDEX('Check giá'!$J$4:$J$203,MATCH($C4,'Check giá'!$A$4:$A$203,0)),"")) -> 250000000 | I4: NCC001 | J4: =IF($I4="","",IFERROR(INDEX('Nhà cung cấp'!$B$4:$B$203,MATCH($I4,'Nhà cung cấp'!$A$4:$A$203,0)),"")) -> Công ty TNHH Thép Việt An | K4: 1180000 | L4: =IF($A4="","",IFERROR($G4*$K4,"")) -> 236000000 | M4: 20 | N4: =IF($I4="","",IFERROR(INDEX('Nhà cung cấp'!$G$4:$G$203,MATCH($I4,'Nhà cung cấp'!$A$4:$A$203,0)),"")) -> 30 | O4: 46061 | P4: =IF($C4="","",IFERROR(_xlfn.MINIFS($L$4:$L$203,$C$4:$C$203,$C4,$L$4:$L$203,">0"),"")) -> 236000000 | Q4: =IF($A4="","",IFERROR($L4-$P4,"")) -> 0 | R4: =IF($A4="","",IFERROR($L4-$H4,"")) -> -14000000 | S4: =IF($A4="","",IFERROR($R4/$H4,"")) -> -0.056 | T4: x | U4: =IF($C4="","",IFERROR(INDEX(PR!$A$4:$A$203,MATCH($C4,PR!$C$4:$C$203,0)),"")) -> PR-2026-001 | V4: VÍ DỤ MẪU – XOÁ TRƯỚC KHI DÙNG THẬT
A5: BG-2026-002 | B5: 46030 | C5: YC-2026-001 | D5: =IF($C5="","",IFERROR(INDEX('Check giá'!$C$4:$C$203,MATCH($C5,'Check giá'!$A$4:$A$203,0)),"")) -> DA-2026-01 | E5: =IF($C5="","",IFERROR(INDEX('Check giá'!$D$4:$D$203,MATCH($C5,'Check giá'!$A$4:$A$203,0)),"")) -> Nhà máy Bao bì Tân Uyên – Giai đoạn 2 | F5: =IF($C5="","",IFERROR(INDEX('Check giá'!$F$4:$F$203,MATCH($C5,'Check giá'!$A$4:$A$203,0)),"")) -> Thép tấm SS400 dày 10mm (1500x6000) | G5: =IF($C5="","",IFERROR(INDEX('Check giá'!$H$4:$H$203,MATCH($C5,'Check giá'!$A$4:$A$203,0)),"")) -> 200 | H5: =IF($C5="","",IFERROR(INDEX('Check giá'!$J$4:$J$203,MATCH($C5,'Check giá'!$A$4:$A$203,0)),"")) -> 250000000 | I5: NCC002 | J5: =IF($I5="","",IFERROR(INDEX('Nhà cung cấp'!$B$4:$B$203,MATCH($I5,'Nhà cung cấp'!$A$4:$A$203,0)),"")) -> Công ty CP Vật tư Hoàng Long | K5: 1205000 | L5: =IF($A5="","",IFERROR($G5*$K5,"")) -> 241000000 | M5: 15 | N5: =IF($I5="","",IFERROR(INDEX('Nhà cung cấp'!$G$4:$G$203,MATCH($I5,'Nhà cung cấp'!$A$4:$A$203,0)),"")) -> 45 | O5: 46061 | P5: =IF($C5="","",IFERROR(_xlfn.MINIFS($L$4:$L$203,$C$4:$C$203,$C5,$L$4:$L$203,">0"),"")) -> 236000000 | Q5: =IF($A5="","",IFERROR($L5-$P5,"")) -> 5000000 | R5: =IF($A5="","",IFERROR($L5-$H5,"")) -> -9000000 | S5: =IF($A5="","",IFERROR($R5/$H5,"")) -> -0.036 | U5: =IF($C5="","",IFERROR(INDEX(PR!$A$4:$A$203,MATCH($C5,PR!$C$4:$C$203,0)),"")) -> PR-2026-001 | V5: VÍ DỤ MẪU – XOÁ TRƯỚC KHI DÙNG THẬT
A6: BG-2026-003 | B6: 46031 | C6: YC-2026-001 | D6: =IF($C6="","",IFERROR(INDEX('Check giá'!$C$4:$C$203,MATCH($C6,'Check giá'!$A$4:$A$203,0)),"")) -> DA-2026-01 | E6: =IF($C6="","",IFERROR(INDEX('Check giá'!$D$4:$D$203,MATCH($C6,'Check giá'!$A$4:$A$203,0)),"")) -> Nhà máy Bao bì Tân Uyên – Giai đoạn 2 | F6: =IF($C6="","",IFERROR(INDEX('Check giá'!$F$4:$F$203,MATCH($C6,'Check giá'!$A$4:$A$203,0)),"")) -> Thép tấm SS400 dày 10mm (1500x6000) | G6: =IF($C6="","",IFERROR(INDEX('Check giá'!$H$4:$H$203,MATCH($C6,'Check giá'!$A$4:$A$203,0)),"")) -> 200 | H6: =IF($C6="","",IFERROR(INDEX('Check giá'!$J$4:$J$203,MATCH($C6,'Check giá'!$A$4:$A$203,0)),"")) -> 250000000 | I6: NCC003 | J6: =IF($I6="","",IFERROR(INDEX('Nhà cung cấp'!$B$4:$B$203,MATCH($I6,'Nhà cung cấp'!$A$4:$A$203,0)),"")) -> Công ty TNHH TM Đại Phát | K6: 1320000 | L6: =IF($A6="","",IFERROR($G6*$K6,"")) -> 264000000 | M6: 10 | N6: =IF($I6="","",IFERROR(INDEX('Nhà cung cấp'!$G$4:$G$203,MATCH($I6,'Nhà cung cấp'!$A$4:$A$203,0)),"")) -> 15 | O6: 46061 | P6: =IF($C6="","",IFERROR(_xlfn.MINIFS($L$4:$L$203,$C$4:$C$203,$C6,$L$4:$L$203,">0"),"")) -> 236000000 | Q6: =IF($A6="","",IFERROR($L6-$P6,"")) -> 28000000 | R6: =IF($A6="","",IFERROR($L6-$H6,"")) -> 14000000 | S6: =IF($A6="","",IFERROR($R6/$H6,"")) -> 0.056 | U6: =IF($C6="","",IFERROR(INDEX(PR!$A$4:$A$203,MATCH($C6,PR!$C$4:$C$203,0)),"")) -> PR-2026-001 | V6: VÍ DỤ MẪU – XOÁ TRƯỚC KHI DÙNG THẬT
D7: =IF($C7="","",IFERROR(INDEX('Check giá'!$C$4:$C$203,MATCH($C7,'Check giá'!$A$4:$A$203,0)),"")) | E7: =IF($C7="","",IFERROR(INDEX('Check giá'!$D$4:$D$203,MATCH($C7,'Check giá'!$A$4:$A$203,0)),"")) | F7: =IF($C7="","",IFERROR(INDEX('Check giá'!$F$4:$F$203,MATCH($C7,'Check giá'!$A$4:$A$203,0)),"")) | G7: =IF($C7="","",IFERROR(INDEX('Check giá'!$H$4:$H$203,MATCH($C7,'Check giá'!$A$4:$A$203,0)),"")) | H7: =IF($C7="","",IFERROR(INDEX('Check giá'!$J$4:$J$203,MATCH($C7,'Check giá'!$A$4:$A$203,0)),"")) | J7: =IF($I7="","",IFERROR(INDEX('Nhà cung cấp'!$B$4:$B$203,MATCH($I7,'Nhà cung cấp'!$A$4:$A$203,0)),"")) | L7: =IF($A7="","",IFERROR($G7*$K7,"")) | N7: =IF($I7="","",IFERROR(INDEX('Nhà cung cấp'!$G$4:$G$203,MATCH($I7,'Nhà cung cấp'!$A$4:$A$203,0)),"")) | P7: =IF($C7="","",IFERROR(_xlfn.MINIFS($L$4:$L$203,$C$4:$C$203,$C7,$L$4:$L$203,">0"),"")) | Q7: =IF($A7="","",IFERROR($L7-$P7,"")) | R7: =IF($A7="","",IFERROR($L7-$H7,"")) | S7: =IF($A7="","",IFERROR($R7/$H7,"")) | U7: =IF($C7="","",IFERROR(INDEX(PR!$A$4:$A$203,MATCH($C7,PR!$C$4:$C$203,0)),""))
D8: =IF($C8="","",IFERROR(INDEX('Check giá'!$C$4:$C$203,MATCH($C8,'Check giá'!$A$4:$A$203,0)),"")) | E8: =IF($C8="","",IFERROR(INDEX('Check giá'!$D$4:$D$203,MATCH($C8,'Check giá'!$A$4:$A$203,0)),"")) | F8: =IF($C8="","",IFERROR(INDEX('Check giá'!$F$4:$F$203,MATCH($C8,'Check giá'!$A$4:$A$203,0)),"")) | G8: =IF($C8="","",IFERROR(INDEX('Check giá'!$H$4:$H$203,MATCH($C8,'Check giá'!$A$4:$A$203,0)),"")) | H8: =IF($C8="","",IFERROR(INDEX('Check giá'!$J$4:$J$203,MATCH($C8,'Check giá'!$A$4:$A$203,0)),"")) | J8: =IF($I8="","",IFERROR(INDEX('Nhà cung cấp'!$B$4:$B$203,MATCH($I8,'Nhà cung cấp'!$A$4:$A$203,0)),"")) | L8: =IF($A8="","",IFERROR($G8*$K8,"")) | N8: =IF($I8="","",IFERROR(INDEX('Nhà cung cấp'!$G$4:$G$203,MATCH($I8,'Nhà cung cấp'!$A$4:$A$203,0)),"")) | P8: =IF($C8="","",IFERROR(_xlfn.MINIFS($L$4:$L$203,$C$4:$C$203,$C8,$L$4:$L$203,">0"),"")) | Q8: =IF($A8="","",IFERROR($L8-$P8,"")) | R8: =IF($A8="","",IFERROR($L8-$H8,"")) | S8: =IF($A8="","",IFERROR($R8/$H8,"")) | U8: =IF($C8="","",IFERROR(INDEX(PR!$A$4:$A$203,MATCH($C8,PR!$C$4:$C$203,0)),""))
D9: =IF($C9="","",IFERROR(INDEX('Check giá'!$C$4:$C$203,MATCH($C9,'Check giá'!$A$4:$A$203,0)),"")) | E9: =IF($C9="","",IFERROR(INDEX('Check giá'!$D$4:$D$203,MATCH($C9,'Check giá'!$A$4:$A$203,0)),"")) | F9: =IF($C9="","",IFERROR(INDEX('Check giá'!$F$4:$F$203,MATCH($C9,'Check giá'!$A$4:$A$203,0)),"")) | G9: =IF($C9="","",IFERROR(INDEX('Check giá'!$H$4:$H$203,MATCH($C9,'Check giá'!$A$4:$A$203,0)),"")) | H9: =IF($C9="","",IFERROR(INDEX('Check giá'!$J$4:$J$203,MATCH($C9,'Check giá'!$A$4:$A$203,0)),"")) | J9: =IF($I9="","",IFERROR(INDEX('Nhà cung cấp'!$B$4:$B$203,MATCH($I9,'Nhà cung cấp'!$A$4:$A$203,0)),"")) | L9: =IF($A9="","",IFERROR($G9*$K9,"")) | N9: =IF($I9="","",IFERROR(INDEX('Nhà cung cấp'!$G$4:$G$203,MATCH($I9,'Nhà cung cấp'!$A$4:$A$203,0)),"")) | P9: =IF($C9="","",IFERROR(_xlfn.MINIFS($L$4:$L$203,$C$4:$C$203,$C9,$L$4:$L$203,">0"),"")) | Q9: =IF($A9="","",IFERROR($L9-$P9,"")) | R9: =IF($A9="","",IFERROR($L9-$H9,"")) | S9: =IF($A9="","",IFERROR($R9/$H9,"")) | U9: =IF($C9="","",IFERROR(INDEX(PR!$A$4:$A$203,MATCH($C9,PR!$C$4:$C$203,0)),""))
D10: =IF($C10="","",IFERROR(INDEX('Check giá'!$C$4:$C$203,MATCH($C10,'Check giá'!$A$4:$A$203,0)),"")) | E10: =IF($C10="","",IFERROR(INDEX('Check giá'!$D$4:$D$203,MATCH($C10,'Check giá'!$A$4:$A$203,0)),"")) | F10: =IF($C10="","",IFERROR(INDEX('Check giá'!$F$4:$F$203,MATCH($C10,'Check giá'!$A$4:$A$203,0)),"")) | G10: =IF($C10="","",IFERROR(INDEX('Check giá'!$H$4:$H$203,MATCH($C10,'Check giá'!$A$4:$A$203,0)),"")) | H10: =IF($C10="","",IFERROR(INDEX('Check giá'!$J$4:$J$203,MATCH($C10,'Check giá'!$A$4:$A$203,0)),"")) | J10: =IF($I10="","",IFERROR(INDEX('Nhà cung cấp'!$B$4:$B$203,MATCH($I10,'Nhà cung cấp'!$A$4:$A$203,0)),"")) | L10: =IF($A10="","",IFERROR($G10*$K10,"")) | N10: =IF($I10="","",IFERROR(INDEX('Nhà cung cấp'!$G$4:$G$203,MATCH($I10,'Nhà cung cấp'!$A$4:$A$203,0)),"")) | P10: =IF($C10="","",IFERROR(_xlfn.MINIFS($L$4:$L$203,$C$4:$C$203,$C10,$L$4:$L$203,">0"),"")) | Q10: =IF($A10="","",IFERROR($L10-$P10,"")) | R10: =IF($A10="","",IFERROR($L10-$H10,"")) | S10: =IF($A10="","",IFERROR($R10/$H10,"")) | U10: =IF($C10="","",IFERROR(INDEX(PR!$A$4:$A$203,MATCH($C10,PR!$C$4:$C$203,0)),""))
D11: =IF($C11="","",IFERROR(INDEX('Check giá'!$C$4:$C$203,MATCH($C11,'Check giá'!$A$4:$A$203,0)),"")) | E11: =IF($C11="","",IFERROR(INDEX('Check giá'!$D$4:$D$203,MATCH($C11,'Check giá'!$A$4:$A$203,0)),"")) | F11: =IF($C11="","",IFERROR(INDEX('Check giá'!$F$4:$F$203,MATCH($C11,'Check giá'!$A$4:$A$203,0)),"")) | G11: =IF($C11="","",IFERROR(INDEX('Check giá'!$H$4:$H$203,MATCH($C11,'Check giá'!$A$4:$A$203,0)),"")) | H11: =IF($C11="","",IFERROR(INDEX('Check giá'!$J$4:$J$203,MATCH($C11,'Check giá'!$A$4:$A$203,0)),"")) | J11: =IF($I11="","",IFERROR(INDEX('Nhà cung cấp'!$B$4:$B$203,MATCH($I11,'Nhà cung cấp'!$A$4:$A$203,0)),"")) | L11: =IF($A11="","",IFERROR($G11*$K11,"")) | N11: =IF($I11="","",IFERROR(INDEX('Nhà cung cấp'!$G$4:$G$203,MATCH($I11,'Nhà cung cấp'!$A$4:$A$203,0)),"")) | P11: =IF($C11="","",IFERROR(_xlfn.MINIFS($L$4:$L$203,$C$4:$C$203,$C11,$L$4:$L$203,">0"),"")) | Q11: =IF($A11="","",IFERROR($L11-$P11,"")) | R11: =IF($A11="","",IFERROR($L11-$H11,"")) | S11: =IF($A11="","",IFERROR($R11/$H11,"")) | U11: =IF($C11="","",IFERROR(INDEX(PR!$A$4:$A$203,MATCH($C11,PR!$C$4:$C$203,0)),""))
D12: =IF($C12="","",IFERROR(INDEX('Check giá'!$C$4:$C$203,MATCH($C12,'Check giá'!$A$4:$A$203,0)),"")) | E12: =IF($C12="","",IFERROR(INDEX('Check giá'!$D$4:$D$203,MATCH($C12,'Check giá'!$A$4:$A$203,0)),"")) | F12: =IF($C12="","",IFERROR(INDEX('Check giá'!$F$4:$F$203,MATCH($C12,'Check giá'!$A$4:$A$203,0)),"")) | G12: =IF($C12="","",IFERROR(INDEX('Check giá'!$H$4:$H$203,MATCH($C12,'Check giá'!$A$4:$A$203,0)),"")) | H12: =IF($C12="","",IFERROR(INDEX('Check giá'!$J$4:$J$203,MATCH($C12,'Check giá'!$A$4:$A$203,0)),"")) | J12: =IF($I12="","",IFERROR(INDEX('Nhà cung cấp'!$B$4:$B$203,MATCH($I12,'Nhà cung cấp'!$A$4:$A$203,0)),"")) | L12: =IF($A12="","",IFERROR($G12*$K12,"")) | N12: =IF($I12="","",IFERROR(INDEX('Nhà cung cấp'!$G$4:$G$203,MATCH($I12,'Nhà cung cấp'!$A$4:$A$203,0)),"")) | P12: =IF($C12="","",IFERROR(_xlfn.MINIFS($L$4:$L$203,$C$4:$C$203,$C12,$L$4:$L$203,">0"),"")) | Q12: =IF($A12="","",IFERROR($L12-$P12,"")) | R12: =IF($A12="","",IFERROR($L12-$H12,"")) | S12: =IF($A12="","",IFERROR($R12/$H12,"")) | U12: =IF($C12="","",IFERROR(INDEX(PR!$A$4:$A$203,MATCH($C12,PR!$C$4:$C$203,0)),""))
D13: =IF($C13="","",IFERROR(INDEX('Check giá'!$C$4:$C$203,MATCH($C13,'Check giá'!$A$4:$A$203,0)),"")) | E13: =IF($C13="","",IFERROR(INDEX('Check giá'!$D$4:$D$203,MATCH($C13,'Check giá'!$A$4:$A$203,0)),"")) | F13: =IF($C13="","",IFERROR(INDEX('Check giá'!$F$4:$F$203,MATCH($C13,'Check giá'!$A$4:$A$203,0)),"")) | G13: =IF($C13="","",IFERROR(INDEX('Check giá'!$H$4:$H$203,MATCH($C13,'Check giá'!$A$4:$A$203,0)),"")) | H13: =IF($C13="","",IFERROR(INDEX('Check giá'!$J$4:$J$203,MATCH($C13,'Check giá'!$A$4:$A$203,0)),"")) | J13: =IF($I13="","",IFERROR(INDEX('Nhà cung cấp'!$B$4:$B$203,MATCH($I13,'Nhà cung cấp'!$A$4:$A$203,0)),"")) | L13: =IF($A13="","",IFERROR($G13*$K13,"")) | N13: =IF($I13="","",IFERROR(INDEX('Nhà cung cấp'!$G$4:$G$203,MATCH($I13,'Nhà cung cấp'!$A$4:$A$203,0)),"")) | P13: =IF($C13="","",IFERROR(_xlfn.MINIFS($L$4:$L$203,$C$4:$C$203,$C13,$L$4:$L$203,">0"),"")) | Q13: =IF($A13="","",IFERROR($L13-$P13,"")) | R13: =IF($A13="","",IFERROR($L13-$H13,"")) | S13: =IF($A13="","",IFERROR($R13/$H13,"")) | U13: =IF($C13="","",IFERROR(INDEX(PR!$A$4:$A$203,MATCH($C13,PR!$C$4:$C$203,0)),""))
D14: =IF($C14="","",IFERROR(INDEX('Check giá'!$C$4:$C$203,MATCH($C14,'Check giá'!$A$4:$A$203,0)),"")) | E14: =IF($C14="","",IFERROR(INDEX('Check giá'!$D$4:$D$203,MATCH($C14,'Check giá'!$A$4:$A$203,0)),"")) | F14: =IF($C14="","",IFERROR(INDEX('Check giá'!$F$4:$F$203,MATCH($C14,'Check giá'!$A$4:$A$203,0)),"")) | G14: =IF($C14="","",IFERROR(INDEX('Check giá'!$H$4:$H$203,MATCH($C14,'Check giá'!$A$4:$A$203,0)),"")) | H14: =IF($C14="","",IFERROR(INDEX('Check giá'!$J$4:$J$203,MATCH($C14,'Check giá'!$A$4:$A$203,0)),"")) | J14: =IF($I14="","",IFERROR(INDEX('Nhà cung cấp'!$B$4:$B$203,MATCH($I14,'Nhà cung cấp'!$A$4:$A$203,0)),"")) | L14: =IF($A14="","",IFERROR($G14*$K14,"")) | N14: =IF($I14="","",IFERROR(INDEX('Nhà cung cấp'!$G$4:$G$203,MATCH($I14,'Nhà cung cấp'!$A$4:$A$203,0)),"")) | P14: =IF($C14="","",IFERROR(_xlfn.MINIFS($L$4:$L$203,$C$4:$C$203,$C14,$L$4:$L$203,">0"),"")) | Q14: =IF($A14="","",IFERROR($L14-$P14,"")) | R14: =IF($A14="","",IFERROR($L14-$H14,"")) | S14: =IF($A14="","",IFERROR($R14/$H14,"")) | U14: =IF($C14="","",IFERROR(INDEX(PR!$A$4:$A$203,MATCH($C14,PR!$C$4:$C$203,0)),""))
D15: =IF($C15="","",IFERROR(INDEX('Check giá'!$C$4:$C$203,MATCH($C15,'Check giá'!$A$4:$A$203,0)),"")) | E15: =IF($C15="","",IFERROR(INDEX('Check giá'!$D$4:$D$203,MATCH($C15,'Check giá'!$A$4:$A$203,0)),"")) | F15: =IF($C15="","",IFERROR(INDEX('Check giá'!$F$4:$F$203,MATCH($C15,'Check giá'!$A$4:$A$203,0)),"")) | G15: =IF($C15="","",IFERROR(INDEX('Check giá'!$H$4:$H$203,MATCH($C15,'Check giá'!$A$4:$A$203,0)),"")) | H15: =IF($C15="","",IFERROR(INDEX('Check giá'!$J$4:$J$203,MATCH($C15,'Check giá'!$A$4:$A$203,0)),"")) | J15: =IF($I15="","",IFERROR(INDEX('Nhà cung cấp'!$B$4:$B$203,MATCH($I15,'Nhà cung cấp'!$A$4:$A$203,0)),"")) | L15: =IF($A15="","",IFERROR($G15*$K15,"")) | N15: =IF($I15="","",IFERROR(INDEX('Nhà cung cấp'!$G$4:$G$203,MATCH($I15,'Nhà cung cấp'!$A$4:$A$203,0)),"")) | P15: =IF($C15="","",IFERROR(_xlfn.MINIFS($L$4:$L$203,$C$4:$C$203,$C15,$L$4:$L$203,">0"),"")) | Q15: =IF($A15="","",IFERROR($L15-$P15,"")) | R15: =IF($A15="","",IFERROR($L15-$H15,"")) | S15: =IF($A15="","",IFERROR($R15/$H15,"")) | U15: =IF($C15="","",IFERROR(INDEX(PR!$A$4:$A$203,MATCH($C15,PR!$C$4:$C$203,0)),""))
D16: =IF($C16="","",IFERROR(INDEX('Check giá'!$C$4:$C$203,MATCH($C16,'Check giá'!$A$4:$A$203,0)),"")) | E16: =IF($C16="","",IFERROR(INDEX('Check giá'!$D$4:$D$203,MATCH($C16,'Check giá'!$A$4:$A$203,0)),"")) | F16: =IF($C16="","",IFERROR(INDEX('Check giá'!$F$4:$F$203,MATCH($C16,'Check giá'!$A$4:$A$203,0)),"")) | G16: =IF($C16="","",IFERROR(INDEX('Check giá'!$H$4:$H$203,MATCH($C16,'Check giá'!$A$4:$A$203,0)),"")) | H16: =IF($C16="","",IFERROR(INDEX('Check giá'!$J$4:$J$203,MATCH($C16,'Check giá'!$A$4:$A$203,0)),"")) | J16: =IF($I16="","",IFERROR(INDEX('Nhà cung cấp'!$B$4:$B$203,MATCH($I16,'Nhà cung cấp'!$A$4:$A$203,0)),"")) | L16: =IF($A16="","",IFERROR($G16*$K16,"")) | N16: =IF($I16="","",IFERROR(INDEX('Nhà cung cấp'!$G$4:$G$203,MATCH($I16,'Nhà cung cấp'!$A$4:$A$203,0)),"")) | P16: =IF($C16="","",IFERROR(_xlfn.MINIFS($L$4:$L$203,$C$4:$C$203,$C16,$L$4:$L$203,">0"),"")) | Q16: =IF($A16="","",IFERROR($L16-$P16,"")) | R16: =IF($A16="","",IFERROR($L16-$H16,"")) | S16: =IF($A16="","",IFERROR($R16/$H16,"")) | U16: =IF($C16="","",IFERROR(INDEX(PR!$A$4:$A$203,MATCH($C16,PR!$C$4:$C$203,0)),""))
D17: =IF($C17="","",IFERROR(INDEX('Check giá'!$C$4:$C$203,MATCH($C17,'Check giá'!$A$4:$A$203,0)),"")) | E17: =IF($C17="","",IFERROR(INDEX('Check giá'!$D$4:$D$203,MATCH($C17,'Check giá'!$A$4:$A$203,0)),"")) | F17: =IF($C17="","",IFERROR(INDEX('Check giá'!$F$4:$F$203,MATCH($C17,'Check giá'!$A$4:$A$203,0)),"")) | G17: =IF($C17="","",IFERROR(INDEX('Check giá'!$H$4:$H$203,MATCH($C17,'Check giá'!$A$4:$A$203,0)),"")) | H17: =IF($C17="","",IFERROR(INDEX('Check giá'!$J$4:$J$203,MATCH($C17,'Check giá'!$A$4:$A$203,0)),"")) | J17: =IF($I17="","",IFERROR(INDEX('Nhà cung cấp'!$B$4:$B$203,MATCH($I17,'Nhà cung cấp'!$A$4:$A$203,0)),"")) | L17: =IF($A17="","",IFERROR($G17*$K17,"")) | N17: =IF($I17="","",IFERROR(INDEX('Nhà cung cấp'!$G$4:$G$203,MATCH($I17,'Nhà cung cấp'!$A$4:$A$203,0)),"")) | P17: =IF($C17="","",IFERROR(_xlfn.MINIFS($L$4:$L$203,$C$4:$C$203,$C17,$L$4:$L$203,">0"),"")) | Q17: =IF($A17="","",IFERROR($L17-$P17,"")) | R17: =IF($A17="","",IFERROR($L17-$H17,"")) | S17: =IF($A17="","",IFERROR($R17/$H17,"")) | U17: =IF($C17="","",IFERROR(INDEX(PR!$A$4:$A$203,MATCH($C17,PR!$C$4:$C$203,0)),""))
D18: =IF($C18="","",IFERROR(INDEX('Check giá'!$C$4:$C$203,MATCH($C18,'Check giá'!$A$4:$A$203,0)),"")) | E18: =IF($C18="","",IFERROR(INDEX('Check giá'!$D$4:$D$203,MATCH($C18,'Check giá'!$A$4:$A$203,0)),"")) | F18: =IF($C18="","",IFERROR(INDEX('Check giá'!$F$4:$F$203,MATCH($C18,'Check giá'!$A$4:$A$203,0)),"")) | G18: =IF($C18="","",IFERROR(INDEX('Check giá'!$H$4:$H$203,MATCH($C18,'Check giá'!$A$4:$A$203,0)),"")) | H18: =IF($C18="","",IFERROR(INDEX('Check giá'!$J$4:$J$203,MATCH($C18,'Check giá'!$A$4:$A$203,0)),"")) | J18: =IF($I18="","",IFERROR(INDEX('Nhà cung cấp'!$B$4:$B$203,MATCH($I18,'Nhà cung cấp'!$A$4:$A$203,0)),"")) | L18: =IF($A18="","",IFERROR($G18*$K18,"")) | N18: =IF($I18="","",IFERROR(INDEX('Nhà cung cấp'!$G$4:$G$203,MATCH($I18,'Nhà cung cấp'!$A$4:$A$203,0)),"")) | P18: =IF($C18="","",IFERROR(_xlfn.MINIFS($L$4:$L$203,$C$4:$C$203,$C18,$L$4:$L$203,">0"),"")) | Q18: =IF($A18="","",IFERROR($L18-$P18,"")) | R18: =IF($A18="","",IFERROR($L18-$H18,"")) | S18: =IF($A18="","",IFERROR($R18/$H18,"")) | U18: =IF($C18="","",IFERROR(INDEX(PR!$A$4:$A$203,MATCH($C18,PR!$C$4:$C$203,0)),""))
... D203: =IF($C203="","",IFERROR(INDEX('Check giá'!$C$4:$C$203,MATCH($C203,'Check giá'!$A$4:$A$203,0)),"")) | E203: =IF($C203="","",IFERROR(INDEX('Check giá'!$D$4:$D$203,MATCH($C203,'Check giá'!$A$4:$A$203,0)),"")) | F203: =IF($C203="","",IFERROR(INDEX('Check giá'!$F$4:$F$203,MATCH($C203,'Check giá'!$A$4:$A$203,0)),"")) | G203: =IF($C203="","",IFERROR(INDEX('Check giá'!$H$4:$H$203,MATCH($C203,'Check giá'!$A$4:$A$203,0)),"")) | H203: =IF($C203="","",IFERROR(INDEX('Check giá'!$J$4:$J$203,MATCH($C203,'Check giá'!$A$4:$A$203,0)),"")) | J203: =IF($I203="","",IFERROR(INDEX('Nhà cung cấp'!$B$4:$B$203,MATCH($I203,'Nhà cung cấp'!$A$4:$A$203,0)),"")) | L203: =IF($A203="","",IFERROR($G203*$K203,"")) | N203: =IF($I203="","",IFERROR(INDEX('Nhà cung cấp'!$G$4:$G$203,MATCH($I203,'Nhà cung cấp'!$A$4:$A$203,0)),"")) | P203: =IF($C203="","",IFERROR(_xlfn.MINIFS($L$4:$L$203,$C$4:$C$203,$C203,$L$4:$L$203,">0"),"")) | Q203: =IF($A203="","",IFERROR($L203-$P203,"")) | R203: =IF($A203="","",IFERROR($L203-$H203,"")) | S203: =IF($A203="","",IFERROR($R203/$H203,"")) | U203: =IF($C203="","",IFERROR(INDEX(PR!$A$4:$A$203,MATCH($C203,PR!$C$4:$C$203,0)),""))

Sheet PR
A1: QUY TRÌNH 2 – ĐỀ NGHỊ MUA HÀNG (PR)
A2: Nhập Mã YC → tự kéo dự án, bộ phận, hạng mục, ĐVT và đơn giá chốt từ bước check giá.
A3: Mã PR | B3: Ngày đề nghị | C3: Mã YC | D3: Mã dự án | E3: Tên dự án | F3: Bộ phận yêu cầu | G3: Hạng mục / Mô tả | H3: ĐVT | I3: Đơn giá chốt từ check giá | J3: Số lượng | K3: Đơn giá dự toán | L3: Giá trị dự toán | M3: Ngày cần hàng | N3: Trạng thái duyệt | O3: Người duyệt | P3: Ngày duyệt | Q3: Ghi chú
A4: PR-2026-001 | B4: 46034 | C4: YC-2026-001 | D4: =IF($C4="","",IFERROR(INDEX('Check giá'!$C$4:$C$203,MATCH($C4,'Check giá'!$A$4:$A$203,0)),"")) -> DA-2026-01 | E4: =IF($C4="","",IFERROR(INDEX('Check giá'!$D$4:$D$203,MATCH($C4,'Check giá'!$A$4:$A$203,0)),"")) -> Nhà máy Bao bì Tân Uyên – Giai đoạn 2 | F4: =IF($C4="","",IFERROR(INDEX('Check giá'!$E$4:$E$203,MATCH($C4,'Check giá'!$A$4:$A$203,0)),"")) -> Phòng Dự án – Trần Văn Nam | G4: =IF($C4="","",IFERROR(INDEX('Check giá'!$F$4:$F$203,MATCH($C4,'Check giá'!$A$4:$A$203,0)),"")) -> Thép tấm SS400 dày 10mm (1500x6000) | H4: =IF($C4="","",IFERROR(INDEX('Check giá'!$G$4:$G$203,MATCH($C4,'Check giá'!$A$4:$A$203,0)),"")) -> Tấm | I4: =IF($C4="","",IFERROR(INDEX('Check giá'!$Q$4:$Q$203,MATCH($C4,'Check giá'!$A$4:$A$203,0)),"")) -> 1180000 | J4: 200 | K4: 1250000 | L4: =IF($A4="","",$J4*$K4) -> 250000000 | M4: 46073 | N4: Đã duyệt | O4: Giám đốc Dự án | P4: 46035 | Q4: VÍ DỤ MẪU – XOÁ TRƯỚC KHI DÙNG THẬT
D5: =IF($C5="","",IFERROR(INDEX('Check giá'!$C$4:$C$203,MATCH($C5,'Check giá'!$A$4:$A$203,0)),"")) | E5: =IF($C5="","",IFERROR(INDEX('Check giá'!$D$4:$D$203,MATCH($C5,'Check giá'!$A$4:$A$203,0)),"")) | F5: =IF($C5="","",IFERROR(INDEX('Check giá'!$E$4:$E$203,MATCH($C5,'Check giá'!$A$4:$A$203,0)),"")) | G5: =IF($C5="","",IFERROR(INDEX('Check giá'!$F$4:$F$203,MATCH($C5,'Check giá'!$A$4:$A$203,0)),"")) | H5: =IF($C5="","",IFERROR(INDEX('Check giá'!$G$4:$G$203,MATCH($C5,'Check giá'!$A$4:$A$203,0)),"")) | I5: =IF($C5="","",IFERROR(INDEX('Check giá'!$Q$4:$Q$203,MATCH($C5,'Check giá'!$A$4:$A$203,0)),"")) | L5: =IF($A5="","",$J5*$K5)
D6: =IF($C6="","",IFERROR(INDEX('Check giá'!$C$4:$C$203,MATCH($C6,'Check giá'!$A$4:$A$203,0)),"")) | E6: =IF($C6="","",IFERROR(INDEX('Check giá'!$D$4:$D$203,MATCH($C6,'Check giá'!$A$4:$A$203,0)),"")) | F6: =IF($C6="","",IFERROR(INDEX('Check giá'!$E$4:$E$203,MATCH($C6,'Check giá'!$A$4:$A$203,0)),"")) | G6: =IF($C6="","",IFERROR(INDEX('Check giá'!$F$4:$F$203,MATCH($C6,'Check giá'!$A$4:$A$203,0)),"")) | H6: =IF($C6="","",IFERROR(INDEX('Check giá'!$G$4:$G$203,MATCH($C6,'Check giá'!$A$4:$A$203,0)),"")) | I6: =IF($C6="","",IFERROR(INDEX('Check giá'!$Q$4:$Q$203,MATCH($C6,'Check giá'!$A$4:$A$203,0)),"")) | L6: =IF($A6="","",$J6*$K6)
D7: =IF($C7="","",IFERROR(INDEX('Check giá'!$C$4:$C$203,MATCH($C7,'Check giá'!$A$4:$A$203,0)),"")) | E7: =IF($C7="","",IFERROR(INDEX('Check giá'!$D$4:$D$203,MATCH($C7,'Check giá'!$A$4:$A$203,0)),"")) | F7: =IF($C7="","",IFERROR(INDEX('Check giá'!$E$4:$E$203,MATCH($C7,'Check giá'!$A$4:$A$203,0)),"")) | G7: =IF($C7="","",IFERROR(INDEX('Check giá'!$F$4:$F$203,MATCH($C7,'Check giá'!$A$4:$A$203,0)),"")) | H7: =IF($C7="","",IFERROR(INDEX('Check giá'!$G$4:$G$203,MATCH($C7,'Check giá'!$A$4:$A$203,0)),"")) | I7: =IF($C7="","",IFERROR(INDEX('Check giá'!$Q$4:$Q$203,MATCH($C7,'Check giá'!$A$4:$A$203,0)),"")) | L7: =IF($A7="","",$J7*$K7)
D8: =IF($C8="","",IFERROR(INDEX('Check giá'!$C$4:$C$203,MATCH($C8,'Check giá'!$A$4:$A$203,0)),"")) | E8: =IF($C8="","",IFERROR(INDEX('Check giá'!$D$4:$D$203,MATCH($C8,'Check giá'!$A$4:$A$203,0)),"")) | F8: =IF($C8="","",IFERROR(INDEX('Check giá'!$E$4:$E$203,MATCH($C8,'Check giá'!$A$4:$A$203,0)),"")) | G8: =IF($C8="","",IFERROR(INDEX('Check giá'!$F$4:$F$203,MATCH($C8,'Check giá'!$A$4:$A$203,0)),"")) | H8: =IF($C8="","",IFERROR(INDEX('Check giá'!$G$4:$G$203,MATCH($C8,'Check giá'!$A$4:$A$203,0)),"")) | I8: =IF($C8="","",IFERROR(INDEX('Check giá'!$Q$4:$Q$203,MATCH($C8,'Check giá'!$A$4:$A$203,0)),"")) | L8: =IF($A8="","",$J8*$K8)
D9: =IF($C9="","",IFERROR(INDEX('Check giá'!$C$4:$C$203,MATCH($C9,'Check giá'!$A$4:$A$203,0)),"")) | E9: =IF($C9="","",IFERROR(INDEX('Check giá'!$D$4:$D$203,MATCH($C9,'Check giá'!$A$4:$A$203,0)),"")) | F9: =IF($C9="","",IFERROR(INDEX('Check giá'!$E$4:$E$203,MATCH($C9,'Check giá'!$A$4:$A$203,0)),"")) | G9: =IF($C9="","",IFERROR(INDEX('Check giá'!$F$4:$F$203,MATCH($C9,'Check giá'!$A$4:$A$203,0)),"")) | H9: =IF($C9="","",IFERROR(INDEX('Check giá'!$G$4:$G$203,MATCH($C9,'Check giá'!$A$4:$A$203,0)),"")) | I9: =IF($C9="","",IFERROR(INDEX('Check giá'!$Q$4:$Q$203,MATCH($C9,'Check giá'!$A$4:$A$203,0)),"")) | L9: =IF($A9="","",$J9*$K9)
D10: =IF($C10="","",IFERROR(INDEX('Check giá'!$C$4:$C$203,MATCH($C10,'Check giá'!$A$4:$A$203,0)),"")) | E10: =IF($C10="","",IFERROR(INDEX('Check giá'!$D$4:$D$203,MATCH($C10,'Check giá'!$A$4:$A$203,0)),"")) | F10: =IF($C10="","",IFERROR(INDEX('Check giá'!$E$4:$E$203,MATCH($C10,'Check giá'!$A$4:$A$203,0)),"")) | G10: =IF($C10="","",IFERROR(INDEX('Check giá'!$F$4:$F$203,MATCH($C10,'Check giá'!$A$4:$A$203,0)),"")) | H10: =IF($C10="","",IFERROR(INDEX('Check giá'!$G$4:$G$203,MATCH($C10,'Check giá'!$A$4:$A$203,0)),"")) | I10: =IF($C10="","",IFERROR(INDEX('Check giá'!$Q$4:$Q$203,MATCH($C10,'Check giá'!$A$4:$A$203,0)),"")) | L10: =IF($A10="","",$J10*$K10)
D11: =IF($C11="","",IFERROR(INDEX('Check giá'!$C$4:$C$203,MATCH($C11,'Check giá'!$A$4:$A$203,0)),"")) | E11: =IF($C11="","",IFERROR(INDEX('Check giá'!$D$4:$D$203,MATCH($C11,'Check giá'!$A$4:$A$203,0)),"")) | F11: =IF($C11="","",IFERROR(INDEX('Check giá'!$E$4:$E$203,MATCH($C11,'Check giá'!$A$4:$A$203,0)),"")) | G11: =IF($C11="","",IFERROR(INDEX('Check giá'!$F$4:$F$203,MATCH($C11,'Check giá'!$A$4:$A$203,0)),"")) | H11: =IF($C11="","",IFERROR(INDEX('Check giá'!$G$4:$G$203,MATCH($C11,'Check giá'!$A$4:$A$203,0)),"")) | I11: =IF($C11="","",IFERROR(INDEX('Check giá'!$Q$4:$Q$203,MATCH($C11,'Check giá'!$A$4:$A$203,0)),"")) | L11: =IF($A11="","",$J11*$K11)
D12: =IF($C12="","",IFERROR(INDEX('Check giá'!$C$4:$C$203,MATCH($C12,'Check giá'!$A$4:$A$203,0)),"")) | E12: =IF($C12="","",IFERROR(INDEX('Check giá'!$D$4:$D$203,MATCH($C12,'Check giá'!$A$4:$A$203,0)),"")) | F12: =IF($C12="","",IFERROR(INDEX('Check giá'!$E$4:$E$203,MATCH($C12,'Check giá'!$A$4:$A$203,0)),"")) | G12: =IF($C12="","",IFERROR(INDEX('Check giá'!$F$4:$F$203,MATCH($C12,'Check giá'!$A$4:$A$203,0)),"")) | H12: =IF($C12="","",IFERROR(INDEX('Check giá'!$G$4:$G$203,MATCH($C12,'Check giá'!$A$4:$A$203,0)),"")) | I12: =IF($C12="","",IFERROR(INDEX('Check giá'!$Q$4:$Q$203,MATCH($C12,'Check giá'!$A$4:$A$203,0)),"")) | L12: =IF($A12="","",$J12*$K12)
D13: =IF($C13="","",IFERROR(INDEX('Check giá'!$C$4:$C$203,MATCH($C13,'Check giá'!$A$4:$A$203,0)),"")) | E13: =IF($C13="","",IFERROR(INDEX('Check giá'!$D$4:$D$203,MATCH($C13,'Check giá'!$A$4:$A$203,0)),"")) | F13: =IF($C13="","",IFERROR(INDEX('Check giá'!$E$4:$E$203,MATCH($C13,'Check giá'!$A$4:$A$203,0)),"")) | G13: =IF($C13="","",IFERROR(INDEX('Check giá'!$F$4:$F$203,MATCH($C13,'Check giá'!$A$4:$A$203,0)),"")) | H13: =IF($C13="","",IFERROR(INDEX('Check giá'!$G$4:$G$203,MATCH($C13,'Check giá'!$A$4:$A$203,0)),"")) | I13: =IF($C13="","",IFERROR(INDEX('Check giá'!$Q$4:$Q$203,MATCH($C13,'Check giá'!$A$4:$A$203,0)),"")) | L13: =IF($A13="","",$J13*$K13)
D14: =IF($C14="","",IFERROR(INDEX('Check giá'!$C$4:$C$203,MATCH($C14,'Check giá'!$A$4:$A$203,0)),"")) | E14: =IF($C14="","",IFERROR(INDEX('Check giá'!$D$4:$D$203,MATCH($C14,'Check giá'!$A$4:$A$203,0)),"")) | F14: =IF($C14="","",IFERROR(INDEX('Check giá'!$E$4:$E$203,MATCH($C14,'Check giá'!$A$4:$A$203,0)),"")) | G14: =IF($C14="","",IFERROR(INDEX('Check giá'!$F$4:$F$203,MATCH($C14,'Check giá'!$A$4:$A$203,0)),"")) | H14: =IF($C14="","",IFERROR(INDEX('Check giá'!$G$4:$G$203,MATCH($C14,'Check giá'!$A$4:$A$203,0)),"")) | I14: =IF($C14="","",IFERROR(INDEX('Check giá'!$Q$4:$Q$203,MATCH($C14,'Check giá'!$A$4:$A$203,0)),"")) | L14: =IF($A14="","",$J14*$K14)
D15: =IF($C15="","",IFERROR(INDEX('Check giá'!$C$4:$C$203,MATCH($C15,'Check giá'!$A$4:$A$203,0)),"")) | E15: =IF($C15="","",IFERROR(INDEX('Check giá'!$D$4:$D$203,MATCH($C15,'Check giá'!$A$4:$A$203,0)),"")) | F15: =IF($C15="","",IFERROR(INDEX('Check giá'!$E$4:$E$203,MATCH($C15,'Check giá'!$A$4:$A$203,0)),"")) | G15: =IF($C15="","",IFERROR(INDEX('Check giá'!$F$4:$F$203,MATCH($C15,'Check giá'!$A$4:$A$203,0)),"")) | H15: =IF($C15="","",IFERROR(INDEX('Check giá'!$G$4:$G$203,MATCH($C15,'Check giá'!$A$4:$A$203,0)),"")) | I15: =IF($C15="","",IFERROR(INDEX('Check giá'!$Q$4:$Q$203,MATCH($C15,'Check giá'!$A$4:$A$203,0)),"")) | L15: =IF($A15="","",$J15*$K15)
D16: =IF($C16="","",IFERROR(INDEX('Check giá'!$C$4:$C$203,MATCH($C16,'Check giá'!$A$4:$A$203,0)),"")) | E16: =IF($C16="","",IFERROR(INDEX('Check giá'!$D$4:$D$203,MATCH($C16,'Check giá'!$A$4:$A$203,0)),"")) | F16: =IF($C16="","",IFERROR(INDEX('Check giá'!$E$4:$E$203,MATCH($C16,'Check giá'!$A$4:$A$203,0)),"")) | G16: =IF($C16="","",IFERROR(INDEX('Check giá'!$F$4:$F$203,MATCH($C16,'Check giá'!$A$4:$A$203,0)),"")) | H16: =IF($C16="","",IFERROR(INDEX('Check giá'!$G$4:$G$203,MATCH($C16,'Check giá'!$A$4:$A$203,0)),"")) | I16: =IF($C16="","",IFERROR(INDEX('Check giá'!$Q$4:$Q$203,MATCH($C16,'Check giá'!$A$4:$A$203,0)),"")) | L16: =IF($A16="","",$J16*$K16)
... D203: =IF($C203="","",IFERROR(INDEX('Check giá'!$C$4:$C$203,MATCH($C203,'Check giá'!$A$4:$A$203,0)),"")) | E203: =IF($C203="","",IFERROR(INDEX('Check giá'!$D$4:$D$203,MATCH($C203,'Check giá'!$A$4:$A$203,0)),"")) | F203: =IF($C203="","",IFERROR(INDEX('Check giá'!$E$4:$E$203,MATCH($C203,'Check giá'!$A$4:$A$203,0)),"")) | G203: =IF($C203="","",IFERROR(INDEX('Check giá'!$F$4:$F$203,MATCH($C203,'Check giá'!$A$4:$A$203,0)),"")) | H203: =IF($C203="","",IFERROR(INDEX('Check giá'!$G$4:$G$203,MATCH($C203,'Check giá'!$A$4:$A$203,0)),"")) | I203: =IF($C203="","",IFERROR(INDEX('Check giá'!$Q$4:$Q$203,MATCH($C203,'Check giá'!$A$4:$A$203,0)),"")) | L203: =IF($A203="","",$J203*$K203)

Sheet PO
A1: QUY TRÌNH 2 – PO MUA HÀNG / HỢP ĐỒNG – TIẾN ĐỘ & CHẤT LƯỢNG
A2: Nhập Mã PR + Mã NCC → tự kéo dự án, hạng mục, bộ phận, dự toán, tên NCC, điều khoản TT. Nhập ngày cam kết/ngày nhận → tự đánh giá tiến độ; nhập SL nhận/SL lỗi → tự chấm chất lượng; hạn TT = ngày nhận + điều khoản NCC.
A3: Mã PO | B3: Ngày PO | C3: Mã PR | D3: Mã dự án | E3: Tên dự án | F3: Hạng mục (từ PR) | G3: Bộ phận yêu cầu | H3: Mã NCC | I3: Tên NCC | J3: Số lượng đặt | K3: Đơn giá PO | L3: Giá trị PO | M3: Dự toán PR | N3: Tiết kiệm đàm phán | O3: Số hợp đồng | P3: Ngày ký hợp đồng | Q3: Ngày giao cam kết | R3: Ngày nhận thực tế | S3: Đánh giá giao hàng | T3: Số ngày trễ | U3: SL nhận thực tế | V3: SL hàng lỗi | W3: Tỷ lệ hàng lỗi | X3: SL trả lại NCC | Y3: Kết quả kiểm tra CL | Z3: Điều khoản TT (ngày) | AA3: Hạn thanh toán | AB3: Ghi chú
A4: PO-2026-001 | B4: 46037 | C4: PR-2026-001 | D4: =IF($C4="","",IFERROR(INDEX(PR!$D$4:$D$203,MATCH($C4,PR!$A$4:$A$203,0)),"")) -> DA-2026-01 | E4: =IF($C4="","",IFERROR(INDEX(PR!$E$4:$E$203,MATCH($C4,PR!$A$4:$A$203,0)),"")) -> Nhà máy Bao bì Tân Uyên – Giai đoạn 2 | F4: =IF($C4="","",IFERROR(INDEX(PR!$G$4:$G$203,MATCH($C4,PR!$A$4:$A$203,0)),"")) -> Thép tấm SS400 dày 10mm (1500x6000) | G4: =IF($C4="","",IFERROR(INDEX(PR!$F$4:$F$203,MATCH($C4,PR!$A$4:$A$203,0)),"")) -> Phòng Dự án – Trần Văn Nam | H4: NCC001 | I4: =IF($H4="","",IFERROR(INDEX('Nhà cung cấp'!$B$4:$B$203,MATCH($H4,'Nhà cung cấp'!$A$4:$A$203,0)),"")) -> Công ty TNHH Thép Việt An | J4: 200 | K4: 1180000 | L4: =IF($A4="","",IFERROR($J4*$K4,"")) -> 236000000 | M4: =IF($C4="","",IFERROR(INDEX(PR!$L$4:$L$203,MATCH($C4,PR!$A$4:$A$203,0)),"")) -> 250000000 | N4: =IF($A4="","",IFERROR($M4-$L4,"")) -> 14000000 | O4: 05/2026/HĐMB-THNG | P4: 46036 | Q4: 46068 | R4: 46071 | S4: =IF($A4="","",IF($Q4="","",IF($R4="",IF(TODAY()>$Q4,"Trễ hạn","Chưa đến hạn"),IF($R4<=$Q4,"Đúng hạn","Giao trễ")))) -> Giao trễ | T4: =IF($A4="","",IF($Q4="",0,IF($R4="",IF(TODAY()>$Q4,TODAY()-$Q4,0),MAX(0,$R4-$Q4)))) -> 3 | U4: 200 | V4: 3 | W4: =IF($A4="","",IFERROR($V4/$U4,"")) -> 0.015 | X4: 3 | Y4: =IF($A4="","",IF($U4="","",IF($W4<='Tổng quan'!$C$8,"Đạt","Không đạt"))) -> Đạt | Z4: =IF($H4="","",IFERROR(INDEX('Nhà cung cấp'!$G$4:$G$203,MATCH($H4,'Nhà cung cấp'!$A$4:$A$203,0)),"")) -> 30 | AA4: =IF($A4="","",IFERROR($R4+$Z4,"")) -> 46101 | AB4: VÍ DỤ MẪU – XOÁ TRƯỚC KHI DÙNG THẬT
D5: =IF($C5="","",IFERROR(INDEX(PR!$D$4:$D$203,MATCH($C5,PR!$A$4:$A$203,0)),"")) | E5: =IF($C5="","",IFERROR(INDEX(PR!$E$4:$E$203,MATCH($C5,PR!$A$4:$A$203,0)),"")) | F5: =IF($C5="","",IFERROR(INDEX(PR!$G$4:$G$203,MATCH($C5,PR!$A$4:$A$203,0)),"")) | G5: =IF($C5="","",IFERROR(INDEX(PR!$F$4:$F$203,MATCH($C5,PR!$A$4:$A$203,0)),"")) | I5: =IF($H5="","",IFERROR(INDEX('Nhà cung cấp'!$B$4:$B$203,MATCH($H5,'Nhà cung cấp'!$A$4:$A$203,0)),"")) | L5: =IF($A5="","",IFERROR($J5*$K5,"")) | M5: =IF($C5="","",IFERROR(INDEX(PR!$L$4:$L$203,MATCH($C5,PR!$A$4:$A$203,0)),"")) | N5: =IF($A5="","",IFERROR($M5-$L5,"")) | S5: =IF($A5="","",IF($Q5="","",IF($R5="",IF(TODAY()>$Q5,"Trễ hạn","Chưa đến hạn"),IF($R5<=$Q5,"Đúng hạn","Giao trễ")))) | T5: =IF($A5="","",IF($Q5="",0,IF($R5="",IF(TODAY()>$Q5,TODAY()-$Q5,0),MAX(0,$R5-$Q5)))) | W5: =IF($A5="","",IFERROR($V5/$U5,"")) | Y5: =IF($A5="","",IF($U5="","",IF($W5<='Tổng quan'!$C$8,"Đạt","Không đạt"))) | Z5: =IF($H5="","",IFERROR(INDEX('Nhà cung cấp'!$G$4:$G$203,MATCH($H5,'Nhà cung cấp'!$A$4:$A$203,0)),"")) | AA5: =IF($A5="","",IFERROR($R5+$Z5,""))
D6: =IF($C6="","",IFERROR(INDEX(PR!$D$4:$D$203,MATCH($C6,PR!$A$4:$A$203,0)),"")) | E6: =IF($C6="","",IFERROR(INDEX(PR!$E$4:$E$203,MATCH($C6,PR!$A$4:$A$203,0)),"")) | F6: =IF($C6="","",IFERROR(INDEX(PR!$G$4:$G$203,MATCH($C6,PR!$A$4:$A$203,0)),"")) | G6: =IF($C6="","",IFERROR(INDEX(PR!$F$4:$F$203,MATCH($C6,PR!$A$4:$A$203,0)),"")) | I6: =IF($H6="","",IFERROR(INDEX('Nhà cung cấp'!$B$4:$B$203,MATCH($H6,'Nhà cung cấp'!$A$4:$A$203,0)),"")) | L6: =IF($A6="","",IFERROR($J6*$K6,"")) | M6: =IF($C6="","",IFERROR(INDEX(PR!$L$4:$L$203,MATCH($C6,PR!$A$4:$A$203,0)),"")) | N6: =IF($A6="","",IFERROR($M6-$L6,"")) | S6: =IF($A6="","",IF($Q6="","",IF($R6="",IF(TODAY()>$Q6,"Trễ hạn","Chưa đến hạn"),IF($R6<=$Q6,"Đúng hạn","Giao trễ")))) | T6: =IF($A6="","",IF($Q6="",0,IF($R6="",IF(TODAY()>$Q6,TODAY()-$Q6,0),MAX(0,$R6-$Q6)))) | W6: =IF($A6="","",IFERROR($V6/$U6,"")) | Y6: =IF($A6="","",IF($U6="","",IF($W6<='Tổng quan'!$C$8,"Đạt","Không đạt"))) | Z6: =IF($H6="","",IFERROR(INDEX('Nhà cung cấp'!$G$4:$G$203,MATCH($H6,'Nhà cung cấp'!$A$4:$A$203,0)),"")) | AA6: =IF($A6="","",IFERROR($R6+$Z6,""))
D7: =IF($C7="","",IFERROR(INDEX(PR!$D$4:$D$203,MATCH($C7,PR!$A$4:$A$203,0)),"")) | E7: =IF($C7="","",IFERROR(INDEX(PR!$E$4:$E$203,MATCH($C7,PR!$A$4:$A$203,0)),"")) | F7: =IF($C7="","",IFERROR(INDEX(PR!$G$4:$G$203,MATCH($C7,PR!$A$4:$A$203,0)),"")) | G7: =IF($C7="","",IFERROR(INDEX(PR!$F$4:$F$203,MATCH($C7,PR!$A$4:$A$203,0)),"")) | I7: =IF($H7="","",IFERROR(INDEX('Nhà cung cấp'!$B$4:$B$203,MATCH($H7,'Nhà cung cấp'!$A$4:$A$203,0)),"")) | L7: =IF($A7="","",IFERROR($J7*$K7,"")) | M7: =IF($C7="","",IFERROR(INDEX(PR!$L$4:$L$203,MATCH($C7,PR!$A$4:$A$203,0)),"")) | N7: =IF($A7="","",IFERROR($M7-$L7,"")) | S7: =IF($A7="","",IF($Q7="","",IF($R7="",IF(TODAY()>$Q7,"Trễ hạn","Chưa đến hạn"),IF($R7<=$Q7,"Đúng hạn","Giao trễ")))) | T7: =IF($A7="","",IF($Q7="",0,IF($R7="",IF(TODAY()>$Q7,TODAY()-$Q7,0),MAX(0,$R7-$Q7)))) | W7: =IF($A7="","",IFERROR($V7/$U7,"")) | Y7: =IF($A7="","",IF($U7="","",IF($W7<='Tổng quan'!$C$8,"Đạt","Không đạt"))) | Z7: =IF($H7="","",IFERROR(INDEX('Nhà cung cấp'!$G$4:$G$203,MATCH($H7,'Nhà cung cấp'!$A$4:$A$203,0)),"")) | AA7: =IF($A7="","",IFERROR($R7+$Z7,""))
D8: =IF($C8="","",IFERROR(INDEX(PR!$D$4:$D$203,MATCH($C8,PR!$A$4:$A$203,0)),"")) | E8: =IF($C8="","",IFERROR(INDEX(PR!$E$4:$E$203,MATCH($C8,PR!$A$4:$A$203,0)),"")) | F8: =IF($C8="","",IFERROR(INDEX(PR!$G$4:$G$203,MATCH($C8,PR!$A$4:$A$203,0)),"")) | G8: =IF($C8="","",IFERROR(INDEX(PR!$F$4:$F$203,MATCH($C8,PR!$A$4:$A$203,0)),"")) | I8: =IF($H8="","",IFERROR(INDEX('Nhà cung cấp'!$B$4:$B$203,MATCH($H8,'Nhà cung cấp'!$A$4:$A$203,0)),"")) | L8: =IF($A8="","",IFERROR($J8*$K8,"")) | M8: =IF($C8="","",IFERROR(INDEX(PR!$L$4:$L$203,MATCH($C8,PR!$A$4:$A$203,0)),"")) | N8: =IF($A8="","",IFERROR($M8-$L8,"")) | S8: =IF($A8="","",IF($Q8="","",IF($R8="",IF(TODAY()>$Q8,"Trễ hạn","Chưa đến hạn"),IF($R8<=$Q8,"Đúng hạn","Giao trễ")))) | T8: =IF($A8="","",IF($Q8="",0,IF($R8="",IF(TODAY()>$Q8,TODAY()-$Q8,0),MAX(0,$R8-$Q8)))) | W8: =IF($A8="","",IFERROR($V8/$U8,"")) | Y8: =IF($A8="","",IF($U8="","",IF($W8<='Tổng quan'!$C$8,"Đạt","Không đạt"))) | Z8: =IF($H8="","",IFERROR(INDEX('Nhà cung cấp'!$G$4:$G$203,MATCH($H8,'Nhà cung cấp'!$A$4:$A$203,0)),"")) | AA8: =IF($A8="","",IFERROR($R8+$Z8,""))
